Workbook

Sheet README
A1: Mono County Respiratory Virus Tracker
A2: Feeds the Respiratory Virus Dashboard (index.html). Update the yellow cells weekly, save, and reload the dashboard.
A4: How to update each week
A5: 1. Weekly_Local: add one row per week (Monday date). Case counts from CalREDIE; admissions, Flu A/B, and vax status from Mammoth Hospital.
A6: 2. Weekly_ELR: enter positive and negative ELR counts; percent positivity is calculated.
A7: 3. Wastewater_Local: enter Verily values for the Mammoth plant and the current UC Davis trend table. These also feed the Cases vs wastewater tab.
A8: 4. State_National: optional manual entry from CDPH Respiratory Virus Report and CalCAT. CDC wastewater and NREVSS positivity load live in the dashboard; these cells are the fallback if the live pull fails.
A9: 5. Flu_Age_Vax: season-to-date flu cases by age group and vaccination status.
A10: 6. Highlights: bullets shown on the dashboard Overview; newest first.
A11: 7. Config: set the current season label and report date.
A13: Conventions
A14: Yellow cells are inputs. Blue-grey cells are formulas; do not type over them.
... A22: 2026-27 rows are pre-dated (Monday 9/7/2026 through 5/31/2027) in Weekly_Local, Weekly_ELR, Wastewater_Local, and State_National. Fill values into the matching week; a dated row with no values is ignored by the dashboard.

Sheet Config
A1: Setting | B1: Value | C1: Notes
A2: Current season | B2: 2026-27 | C2: Label shown in the dashboard; format YYYY-YY
A3: Season start date | B3: 46272 | C3: Monday of the first week of the season (MMWR week 36). For 2026 that is 9/7/2026.
A4: Report date | B4: 46280 | C4: Shown on the dashboard header and print cover
A5: Jurisdiction | B5: Mono County
A6: Wastewater site name | B6: Mammoth Lakes (Verily) | C6: Label for the local wastewater series
A7: Prepared by | B7: Mono County Health & Human Services, Public Health Division
A8: Wastewater note | B8: Wastewater sampling paused after 9/9/2026 (Verily contract ended 9/14/2026); resumes late September 2026 under a new contract. | C8: Shown on the wastewater panels; clear it when sampling resumes

Sheet Weekly_Local
A1: Week (Mon) | B1: Covid-19 cases | C1: Flu cases | D1: RSV cases | E1: MH Covid (total) | F1: MH Covid (local) | G1: MH Flu (total) | H1: MH Flu (local) | I1: MH RSV (total) | J1: MH RSV (local) | K1: MH Flu A | L1: MH Flu B | M1: MH Flu A+B | N1: MH Flu vax 'Yes' | O1: MH Flu vax 'No'/'Unknown' | P1: MH Flu vax rate | Q1: Notes | R1: Week ending (Sat) | S1: MMWR year | T1: MMWR week | U1: Season
A2: 44893 | B2: 2 | C2: 2 | M2: =IF(AND(K2="",L2=""),"",SUM(K2:L2)) | P2: =IF(OR(M2="",M2=0),"",IF(N2="",0,N2)/M2) | R2: =A2+5 -> 44898 | S2: =IF(R2>=DATE(YEAR(R2)+1,1,4)-WEEKDAY(DATE(YEAR(R2)+1,1,4))+1,YEAR(R2)+1,IF(R2<DATE(YEAR(R2),1,4)-WEEKDAY(DATE(YEAR(R2),1,4))+1,YEAR(R2)-1,YEAR(R2))) -> 2022 | T2: =INT((R2-(DATE(S2,1,4)-WEEKDAY(DATE(S2,1,4))+1))/7)+1 -> 48 | U2: =IF(T2>=36,S2&"-"&RIGHT(S2+1,2),(S2-1)&"-"&RIGHT(S2,2)) -> 2022-23
A3: 44900 | B3: 8 | C3: 2 | M3: =IF(AND(K3="",L3=""),"",SUM(K3:L3)) | P3: =IF(OR(M3="",M3=0),"",IF(N3="",0,N3)/M3) | R3: =A3+5 -> 44905 | S3: =IF(R3>=DATE(YEAR(R3)+1,1,4)-WEEKDAY(DATE(YEAR(R3)+1,1,4))+1,YEAR(R3)+1,IF(R3<DATE(YEAR(R3),1,4)-WEEKDAY(DATE(YEAR(R3),1,4))+1,YEAR(R3)-1,YEAR(R3))) -> 2022 | T3: =INT((R3-(DATE(S3,1,4)-WEEKDAY(DATE(S3,1,4))+1))/7)+1 -> 49 | U3: =IF(T3>=36,S3&"-"&RIGHT(S3+1,2),(S3-1)&"-"&RIGHT(S3,2)) -> 2022-23
A4: 44907 | B4: 5 | C4: 3 | M4: =IF(AND(K4="",L4=""),"",SUM(K4:L4)) | P4: =IF(OR(M4="",M4=0),"",IF(N4="",0,N4)/M4) | R4: =A4+5 -> 44912 | S4: =IF(R4>=DATE(YEAR(R4)+1,1,4)-WEEKDAY(DATE(YEAR(R4)+1,1,4))+1,YEAR(R4)+1,IF(R4<DATE(YEAR(R4),1,4)-WEEKDAY(DATE(YEAR(R4),1,4))+1,YEAR(R4)-1,YEAR(R4))) -> 2022 | T4: =INT((R4-(DATE(S4,1,4)-WEEKDAY(DATE(S4,1,4))+1))/7)+1 -> 50 | U4: =IF(T4>=36,S4&"-"&RIGHT(S4+1,2),(S4-1)&"-"&RIGHT(S4,2)) -> 2022-23
A5: 44914 | B5: 16 | C5: 1 | D5: 1 | M5: =IF(AND(K5="",L5=""),"",SUM(K5:L5)) | P5: =IF(OR(M5="",M5=0),"",IF(N5="",0,N5)/M5) | R5: =A5+5 -> 44919 | S5: =IF(R5>=DATE(YEAR(R5)+1,1,4)-WEEKDAY(DATE(YEAR(R5)+1,1,4))+1,YEAR(R5)+1,IF(R5<DATE(YEAR(R5),1,4)-WEEKDAY(DATE(YEAR(R5),1,4))+1,YEAR(R5)-1,YEAR(R5))) -> 2022 | T5: =INT((R5-(DATE(S5,1,4)-WEEKDAY(DATE(S5,1,4))+1))/7)+1 -> 51 | U5: =IF(T5>=36,S5&"-"&RIGHT(S5+1,2),(S5-1)&"-"&RIGHT(S5,2)) -> 2022-23
A6: 44921 | B6: 18 | C6: 1 | D6: 0 | M6: =IF(AND(K6="",L6=""),"",SUM(K6:L6)) | P6: =IF(OR(M6="",M6=0),"",IF(N6="",0,N6)/M6) | R6: =A6+5 -> 44926 | S6: =IF(R6>=DATE(YEAR(R6)+1,1,4)-WEEKDAY(DATE(YEAR(R6)+1,1,4))+1,YEAR(R6)+1,IF(R6<DATE(YEAR(R6),1,4)-WEEKDAY(DATE(YEAR(R6),1,4))+1,YEAR(R6)-1,YEAR(R6))) -> 2022 | T6: =INT((R6-(DATE(S6,1,4)-WEEKDAY(DATE(S6,1,4))+1))/7)+1 -> 52 | U6: =IF(T6>=36,S6&"-"&RIGHT(S6+1,2),(S6-1)&"-"&RIGHT(S6,2)) -> 2022-23
A7: 44928 | B7: 13 | C7: 1 | D7: 1 | M7: =IF(AND(K7="",L7=""),"",SUM(K7:L7)) | P7: =IF(OR(M7="",M7=0),"",IF(N7="",0,N7)/M7) | R7: =A7+5 -> 44933 | S7: =IF(R7>=DATE(YEAR(R7)+1,1,4)-WEEKDAY(DATE(YEAR(R7)+1,1,4))+1,YEAR(R7)+1,IF(R7<DATE(YEAR(R7),1,4)-WEEKDAY(DATE(YEAR(R7),1,4))+1,YEAR(R7)-1,YEAR(R7))) -> 2023 | T7: =INT((R7-(DATE(S7,1,4)-WEEKDAY(DATE(S7,1,4))+1))/7)+1 -> 1 | U7: =IF(T7>=36,S7&"-"&RIGHT(S7+1,2),(S7-1)&"-"&RIGHT(S7,2)) -> 2022-23
A8: 44935 | B8: 9 | C8: 0 | D8: 0 | M8: =IF(AND(K8="",L8=""),"",SUM(K8:L8)) | P8: =IF(OR(M8="",M8=0),"",IF(N8="",0,N8)/M8) | R8: =A8+5 -> 44940 | S8: =IF(R8>=DATE(YEAR(R8)+1,1,4)-WEEKDAY(DATE(YEAR(R8)+1,1,4))+1,YEAR(R8)+1,IF(R8<DATE(YEAR(R8),1,4)-WEEKDAY(DATE(YEAR(R8),1,4))+1,YEAR(R8)-1,YEAR(R8))) -> 2023 | T8: =INT((R8-(DATE(S8,1,4)-WEEKDAY(DATE(S8,1,4))+1))/7)+1 -> 2 | U8: =IF(T8>=36,S8&"-"&RIGHT(S8+1,2),(S8-1)&"-"&RIGHT(S8,2)) -> 2022-23
A9: 44942 | B9: 6 | C9: 0 | D9: 0 | M9: =IF(AND(K9="",L9=""),"",SUM(K9:L9)) | P9: =IF(OR(M9="",M9=0),"",IF(N9="",0,N9)/M9) | R9: =A9+5 -> 44947 | S9: =IF(R9>=DATE(YEAR(R9)+1,1,4)-WEEKDAY(DATE(YEAR(R9)+1,1,4))+1,YEAR(R9)+1,IF(R9<DATE(YEAR(R9),1,4)-WEEKDAY(DATE(YEAR(R9),1,4))+1,YEAR(R9)-1,YEAR(R9))) -> 2023 | T9: =INT((R9-(DATE(S9,1,4)-WEEKDAY(DATE(S9,1,4))+1))/7)+1 -> 3 | U9: =IF(T9>=36,S9&"-"&RIGHT(S9+1,2),(S9-1)&"-"&RIGHT(S9,2)) -> 2022-23
A10: 44949 | B10: 5 | C10: 0 | D10: 0 | M10: =IF(AND(K10="",L10=""),"",SUM(K10:L10)) | P10: =IF(OR(M10="",M10=0),"",IF(N10="",0,N10)/M10) | R10: =A10+5 -> 44954 | S10: =IF(R10>=DATE(YEAR(R10)+1,1,4)-WEEKDAY(DATE(YEAR(R10)+1,1,4))+1,YEAR(R10)+1,IF(R10<DATE(YEAR(R10),1,4)-WEEKDAY(DATE(YEAR(R10),1,4))+1,YEAR(R10)-1,YEAR(R10))) -> 2023 | T10: =INT((R10-(DATE(S10,1,4)-WEEKDAY(DATE(S10,1,4))+1))/7)+1 -> 4 | U10: =IF(T10>=36,S10&"-"&RIGHT(S10+1,2),(S10-1)&"-"&RIGHT(S10,2)) -> 2022-23
A11: 44956 | B11: 5 | C11: 0 | D11: 0 | M11: =IF(AND(K11="",L11=""),"",SUM(K11:L11)) | P11: =IF(OR(M11="",M11=0),"",IF(N11="",0,N11)/M11) | R11: =A11+5 -> 44961 | S11: =IF(R11>=DATE(YEAR(R11)+1,1,4)-WEEKDAY(DATE(YEAR(R11)+1,1,4))+1,YEAR(R11)+1,IF(R11<DATE(YEAR(R11),1,4)-WEEKDAY(DATE(YEAR(R11),1,4))+1,YEAR(R11)-1,YEAR(R11))) -> 2023 | T11: =INT((R11-(DATE(S11,1,4)-WEEKDAY(DATE(S11,1,4))+1))/7)+1 -> 5 | U11: =IF(T11>=36,S11&"-"&RIGHT(S11+1,2),(S11-1)&"-"&RIGHT(S11,2)) -> 2022-23
A12: 44963 | B12: 3 | C12: 2 | D12: 0 | M12: =IF(AND(K12="",L12=""),"",SUM(K12:L12)) | P12: =IF(OR(M12="",M12=0),"",IF(N12="",0,N12)/M12) | R12: =A12+5 -> 44968 | S12: =IF(R12>=DATE(YEAR(R12)+1,1,4)-WEEKDAY(DATE(YEAR(R12)+1,1,4))+1,YEAR(R12)+1,IF(R12<DATE(YEAR(R12),1,4)-WEEKDAY(DATE(YEAR(R12),1,4))+1,YEAR(R12)-1,YEAR(R12))) -> 2023 | T12: =INT((R12-(DATE(S12,1,4)-WEEKDAY(DATE(S12,1,4))+1))/7)+1 -> 6 | U12: =IF(T12>=36,S12&"-"&RIGHT(S12+1,2),(S12-1)&"-"&RIGHT(S12,2)) -> 2022-23
A13: 44970 | B13: 2 | C13: 0 | D13: 0 | M13: =IF(AND(K13="",L13=""),"",SUM(K13:L13)) | P13: =IF(OR(M13="",M13=0),"",IF(N13="",0,N13)/M13) | R13: =A13+5 -> 44975 | S13: =IF(R13>=DATE(YEAR(R13)+1,1,4)-WEEKDAY(DATE(YEAR(R13)+1,1,4))+1,YEAR(R13)+1,IF(R13<DATE(YEAR(R13),1,4)-WEEKDAY(DATE(YEAR(R13),1,4))+1,YEAR(R13)-1,YEAR(R13))) -> 2023 | T13: =INT((R13-(DATE(S13,1,4)-WEEKDAY(DATE(S13,1,4))+1))/7)+1 -> 7 | U13: =IF(T13>=36,S13&"-"&RIGHT(S13+1,2),(S13-1)&"-"&RIGHT(S13,2)) -> 2022-23
A14: 44977 | B14: 5 | C14: 0 | D14: 0 | M14: =IF(AND(K14="",L14=""),"",SUM(K14:L14)) | P14: =IF(OR(M14="",M14=0),"",IF(N14="",0,N14)/M14) | R14: =A14+5 -> 44982 | S14: =IF(R14>=DATE(YEAR(R14)+1,1,4)-WEEKDAY(DATE(YEAR(R14)+1,1,4))+1,YEAR(R14)+1,IF(R14<DATE(YEAR(R14),1,4)-WEEKDAY(DATE(YEAR(R14),1,4))+1,YEAR(R14)-1,YEAR(R14))) -> 2023 | T14: =INT((R14-(DATE(S14,1,4)-WEEKDAY(DATE(S14,1,4))+1))/7)+1 -> 8 | U14: =IF(T14>=36,S14&"-"&RIGHT(S14+1,2),(S14-1)&"-"&RIGHT(S14,2)) -> 2022-23
A15: 44984 | B15: 4 | C15: 0 | D15: 0 | M15: =IF(AND(K15="",L15=""),"",SUM(K15:L15)) | P15: =IF(OR(M15="",M15=0),"",IF(N15="",0,N15)/M15) | R15: =A15+5 -> 44989 | S15: =IF(R15>=DATE(YEAR(R15)+1,1,4)-WEEKDAY(DATE(YEAR(R15)+1,1,4))+1,YEAR(R15)+1,IF(R15<DATE(YEAR(R15),1,4)-WEEKDAY(DATE(YEAR(R15),1,4))+1,YEAR(R15)-1,YEAR(R15))) -> 2023 | T15: =INT((R15-(DATE(S15,1,4)-WEEKDAY(DATE(S15,1,4))+1))/7)+1 -> 9 | U15: =IF(T15>=36,S15&"-"&RIGHT(S15+1,2),(S15-1)&"-"&RIGHT(S15,2)) -> 2022-23
A16: 44991 | B16: 3 | C16: 0 | D16: 0 | M16: =IF(AND(K16="",L16=""),"",SUM(K16:L16)) | P16: =IF(OR(M16="",M16=0),"",IF(N16="",0,N16)/M16) | R16: =A16+5 -> 44996 | S16: =IF(R16>=DATE(YEAR(R16)+1,1,4)-WEEKDAY(DATE(YEAR(R16)+1,1,4))+1,YEAR(R16)+1,IF(R16<DATE(YEAR(R16),1,4)-WEEKDAY(DATE(YEAR(R16),1,4))+1,YEAR(R16)-1,YEAR(R16))) -> 2023 | T16: =INT((R16-(DATE(S16,1,4)-WEEKDAY(DATE(S16,1,4))+1))/7)+1 -> 10 | U16: =IF(T16>=36,S16&"-"&RIGHT(S16+1,2),(S16-1)&"-"&RIGHT(S16,2)) -> 2022-23
... A43: 45180 | B43: 5 | C43: 0 | D43: 0 | M43: =IF(AND(K43="",L43=""),"",SUM(K43:L43)) | P43: =IF(OR(M43="",M43=0),"",IF(N43="",0,N43)/M43) | R43: =A43+5 -> 45185 | S43: =IF(R43>=DATE(YEAR(R43)+1,1,4)-WEEKDAY(DATE(YEAR(R43)+1,1,4))+1,YEAR(R43)+1,IF(R43<DATE(YEAR(R43),1,4)-WEEKDAY(DATE(YEAR(R43),1,4))+1,YEAR(R43)-1,YEAR(R43))) -> 2023 | T43: =INT((R43-(DATE(S43,1,4)-WEEKDAY(DATE(S43,1,4))+1))/7)+1 -> 37 | U43: =IF(T43>=36,S43&"-"&RIGHT(S43+1,2),(S43-1)&"-"&RIGHT(S43,2)) -> 2023-24
A44: 45187 | B44: 6 | C44: 2 | D44: 1 | E44: 2 | F44: 0 | G44: 0 | H44: 0 | I44: 0 | J44: 0 | K44: 0 | L44: 0 | M44: =IF(AND(K44="",L44=""),"",SUM(K44:L44)) -> 0 | P44: =IF(OR(M44="",M44=0),"",IF(N44="",0,N44)/M44) | Q44: MH data from Winter23Tracker | R44: =A44+5 -> 45192 | S44: =IF(R44>=DATE(YEAR(R44)+1,1,4)-WEEKDAY(DATE(YEAR(R44)+1,1,4))+1,YEAR(R44)+1,IF(R44<DATE(YEAR(R44),1,4)-WEEKDAY(DATE(YEAR(R44),1,4))+1,YEAR(R44)-1,YEAR(R44))) -> 2023 | T44: =INT((R44-(DATE(S44,1,4)-WEEKDAY(DATE(S44,1,4))+1))/7)+1 -> 38 | U44: =IF(T44>=36,S44&"-"&RIGHT(S44+1,2),(S44-1)&"-"&RIGHT(S44,2)) -> 2023-24
A45: 45194 | B45: 5 | C45: 0 | D45: 0 | E45: 0 | F45: 0 | G45: 1 | H45: 0 | I45: 0 | J45: 0 | K45: 1 | L45: 0 | M45: =IF(AND(K45="",L45=""),"",SUM(K45:L45)) -> 1 | P45: =IF(OR(M45="",M45=0),"",IF(N45="",0,N45)/M45) -> 0 | Q45: MH data from Winter23Tracker | R45: =A45+5 -> 45199 | S45: =IF(R45>=DATE(YEAR(R45)+1,1,4)-WEEKDAY(DATE(YEAR(R45)+1,1,4))+1,YEAR(R45)+1,IF(R45<DATE(YEAR(R45),1,4)-WEEKDAY(DATE(YEAR(R45),1,4))+1,YEAR(R45)-1,YEAR(R45))) -> 2023 | T45: =INT((R45-(DATE(S45,1,4)-WEEKDAY(DATE(S45,1,4))+1))/7)+1 -> 39 | U45: =IF(T45>=36,S45&"-"&RIGHT(S45+1,2),(S45-1)&"-"&RIGHT(S45,2)) -> 2023-24
A46: 45201 | B46: 1 | C46: 0 | D46: 0 | E46: 0 | F46: 0 | G46: 0 | H46: 0 | I46: 0 | J46: 0 | K46: 0 | L46: 0 | M46: =IF(AND(K46="",L46=""),"",SUM(K46:L46)) -> 0 | P46: =IF(OR(M46="",M46=0),"",IF(N46="",0,N46)/M46) | Q46: MH data from Winter23Tracker | R46: =A46+5 -> 45206 | S46: =IF(R46>=DATE(YEAR(R46)+1,1,4)-WEEKDAY(DATE(YEAR(R46)+1,1,4))+1,YEAR(R46)+1,IF(R46<DATE(YEAR(R46),1,4)-WEEKDAY(DATE(YEAR(R46),1,4))+1,YEAR(R46)-1,YEAR(R46))) -> 2023 | T46: =INT((R46-(DATE(S46,1,4)-WEEKDAY(DATE(S46,1,4))+1))/7)+1 -> 40 | U46: =IF(T46>=36,S46&"-"&RIGHT(S46+1,2),(S46-1)&"-"&RIGHT(S46,2)) -> 2023-24
A47: 45208 | B47: 14 | C47: 0 | D47: 0 | E47: 0 | F47: 0 | G47: 0 | H47: 0 | I47: 1 | J47: 0 | K47: 0 | L47: 0 | M47: =IF(AND(K47="",L47=""),"",SUM(K47:L47)) -> 0 | P47: =IF(OR(M47="",M47=0),"",IF(N47="",0,N47)/M47) | Q47: MH data from Winter23Tracker | R47: =A47+5 -> 45213 | S47: =IF(R47>=DATE(YEAR(R47)+1,1,4)-WEEKDAY(DATE(YEAR(R47)+1,1,4))+1,YEAR(R47)+1,IF(R47<DATE(YEAR(R47),1,4)-WEEKDAY(DATE(YEAR(R47),1,4))+1,YEAR(R47)-1,YEAR(R47))) -> 2023 | T47: =INT((R47-(DATE(S47,1,4)-WEEKDAY(DATE(S47,1,4))+1))/7)+1 -> 41 | U47: =IF(T47>=36,S47&"-"&RIGHT(S47+1,2),(S47-1)&"-"&RIGHT(S47,2)) -> 2023-24
A48: 45215 | B48: 7 | C48: 0 | D48: 0 | E48: 0 | F48: 0 | G48: 0 | H48: 0 | I48: 0 | J48: 0 | K48: 0 | L48: 0 | M48: =IF(AND(K48="",L48=""),"",SUM(K48:L48)) -> 0 | P48: =IF(OR(M48="",M48=0),"",IF(N48="",0,N48)/M48) | Q48: MH data from Winter23Tracker | R48: =A48+5 -> 45220 | S48: =IF(R48>=DATE(YEAR(R48)+1,1,4)-WEEKDAY(DATE(YEAR(R48)+1,1,4))+1,YEAR(R48)+1,IF(R48<DATE(YEAR(R48),1,4)-WEEKDAY(DATE(YEAR(R48),1,4))+1,YEAR(R48)-1,YEAR(R48))) -> 2023 | T48: =INT((R48-(DATE(S48,1,4)-WEEKDAY(DATE(S48,1,4))+1))/7)+1 -> 42 | U48: =IF(T48>=36,S48&"-"&RIGHT(S48+1,2),(S48-1)&"-"&RIGHT(S48,2)) -> 2023-24
A49: 45222 | B49: 0 | C49: 0 | D49: 0 | E49: 0 | F49: 0 | G49: 2 | H49: 0 | I49: 1 | J49: 0 | K49: 0 | L49: 2 | M49: =IF(AND(K49="",L49=""),"",SUM(K49:L49)) -> 2 | P49: =IF(OR(M49="",M49=0),"",IF(N49="",0,N49)/M49) -> 0 | Q49: MH data from Winter23Tracker | R49: =A49+5 -> 45227 | S49: =IF(R49>=DATE(YEAR(R49)+1,1,4)-WEEKDAY(DATE(YEAR(R49)+1,1,4))+1,YEAR(R49)+1,IF(R49<DATE(YEAR(R49),1,4)-WEEKDAY(DATE(YEAR(R49),1,4))+1,YEAR(R49)-1,YEAR(R49))) -> 2023 | T49: =INT((R49-(DATE(S49,1,4)-WEEKDAY(DATE(S49,1,4))+1))/7)+1 -> 43 | U49: =IF(T49>=36,S49&"-"&RIGHT(S49+1,2),(S49-1)&"-"&RIGHT(S49,2)) -> 2023-24
A50: 45229 | B50: 13 | C50: 0 | D50: 1 | E50: 0 | F50: 0 | G50: 0 | H50: 0 | I50: 0 | J50: 0 | K50: 0 | L50: 0 | M50: =IF(AND(K50="",L50=""),"",SUM(K50:L50)) -> 0 | P50: =IF(OR(M50="",M50=0),"",IF(N50="",0,N50)/M50) | Q50: MH data from Winter23Tracker | R50: =A50+5 -> 45234 | S50: =IF(R50>=DATE(YEAR(R50)+1,1,4)-WEEKDAY(DATE(YEAR(R50)+1,1,4))+1,YEAR(R50)+1,IF(R50<DATE(YEAR(R50),1,4)-WEEKDAY(DATE(YEAR(R50),1,4))+1,YEAR(R50)-1,YEAR(R50))) -> 2023 | T50: =INT((R50-(DATE(S50,1,4)-WEEKDAY(DATE(S50,1,4))+1))/7)+1 -> 44 | U50: =IF(T50>=36,S50&"-"&RIGHT(S50+1,2),(S50-1)&"-"&RIGHT(S50,2)) -> 2023-24
A51: 45236 | B51: 6 | C51: 0 | D51: 1 | E51: 0 | F51: 0 | G51: 0 | H51: 0 | I51: 1 | J51: 1 | K51: 0 | L51: 0 | M51: =IF(AND(K51="",L51=""),"",SUM(K51:L51)) -> 0 | P51: =IF(OR(M51="",M51=0),"",IF(N51="",0,N51)/M51) | Q51: MH data from Winter23Tracker | R51: =A51+5 -> 45241 | S51: =IF(R51>=DATE(YEAR(R51)+1,1,4)-WEEKDAY(DATE(YEAR(R51)+1,1,4))+1,YEAR(R51)+1,IF(R51<DATE(YEAR(R51),1,4)-WEEKDAY(DATE(YEAR(R51),1,4))+1,YEAR(R51)-1,YEAR(R51))) -> 2023 | T51: =INT((R51-(DATE(S51,1,4)-WEEKDAY(DATE(S51,1,4))+1))/7)+1 -> 45 | U51: =IF(T51>=36,S51&"-"&RIGHT(S51+1,2),(S51-1)&"-"&RIGHT(S51,2)) -> 2023-24
A52: 45243 | B52: 0 | C52: 4 | D52: 0 | E52: 0 | F52: 0 | G52: 4 | H52: 3 | I52: 1 | J52: 0 | K52: 4 | L52: 0 | M52: =IF(AND(K52="",L52=""),"",SUM(K52:L52)) -> 4 | P52: =IF(OR(M52="",M52=0),"",IF(N52="",0,N52)/M52) -> 0 | Q52: MH data from Winter23Tracker | R52: =A52+5 -> 45248 | S52: =IF(R52>=DATE(YEAR(R52)+1,1,4)-WEEKDAY(DATE(YEAR(R52)+1,1,4))+1,YEAR(R52)+1,IF(R52<DATE(YEAR(R52),1,4)-WEEKDAY(DATE(YEAR(R52),1,4))+1,YEAR(R52)-1,YEAR(R52))) -> 2023 | T52: =INT((R52-(DATE(S52,1,4)-WEEKDAY(DATE(S52,1,4))+1))/7)+1 -> 46 | U52: =IF(T52>=36,S52&"-"&RIGHT(S52+1,2),(S52-1)&"-"&RIGHT(S52,2)) -> 2023-24
A53: 45250 | B53: 2 | C53: 2 | D53: 3 | E53: 0 | F53: 0 | G53: 3 | H53: 2 | I53: 6 | J53: 1 | K53: 3 | L53: 0 | M53: =IF(AND(K53="",L53=""),"",SUM(K53:L53)) -> 3 | P53: =IF(OR(M53="",M53=0),"",IF(N53="",0,N53)/M53) -> 0 | Q53: MH data from Winter23Tracker | R53: =A53+5 -> 45255 | S53: =IF(R53>=DATE(YEAR(R53)+1,1,4)-WEEKDAY(DATE(YEAR(R53)+1,1,4))+1,YEAR(R53)+1,IF(R53<DATE(YEAR(R53),1,4)-WEEKDAY(DATE(YEAR(R53),1,4))+1,YEAR(R53)-1,YEAR(R53))) -> 2023 | T53: =INT((R53-(DATE(S53,1,4)-WEEKDAY(DATE(S53,1,4))+1))/7)+1 -> 47 | U53: =IF(T53>=36,S53&"-"&RIGHT(S53+1,2),(S53-1)&"-"&RIGHT(S53,2)) -> 2023-24
A54: 45257 | B54: 9 | C54: 4 | D54: 0 | E54: 0 | F54: 0 | G54: 4 | H54: 2 | I54: 1 | J54: 1 | K54: 4 | L54: 0 | M54: =IF(AND(K54="",L54=""),"",SUM(K54:L54)) -> 4 | P54: =IF(OR(M54="",M54=0),"",IF(N54="",0,N54)/M54) -> 0 | Q54: MH data from Winter23Tracker | R54: =A54+5 -> 45262 | S54: =IF(R54>=DATE(YEAR(R54)+1,1,4)-WEEKDAY(DATE(YEAR(R54)+1,1,4))+1,YEAR(R54)+1,IF(R54<DATE(YEAR(R54),1,4)-WEEKDAY(DATE(YEAR(R54),1,4))+1,YEAR(R54)-1,YEAR(R54))) -> 2023 | T54: =INT((R54-(DATE(S54,1,4)-WEEKDAY(DATE(S54,1,4))+1))/7)+1 -> 48 | U54: =IF(T54>=36,S54&"-"&RIGHT(S54+1,2),(S54-1)&"-"&RIGHT(S54,2)) -> 2023-24
A55: 45264 | B55: 4 | C55: 1 | D55: 1 | E55: 0 | F55: 0 | G55: 0 | H55: 0 | I55: 1 | J55: 1 | K55: 0 | L55: 0 | M55: =IF(AND(K55="",L55=""),"",SUM(K55:L55)) -> 0 | P55: =IF(OR(M55="",M55=0),"",IF(N55="",0,N55)/M55) | Q55: MH data from Winter23Tracker | R55: =A55+5 -> 45269 | S55: =IF(R55>=DATE(YEAR(R55)+1,1,4)-WEEKDAY(DATE(YEAR(R55)+1,1,4))+1,YEAR(R55)+1,IF(R55<DATE(YEAR(R55),1,4)-WEEKDAY(DATE(YEAR(R55),1,4))+1,YEAR(R55)-1,YEAR(R55))) -> 2023 | T55: =INT((R55-(DATE(S55,1,4)-WEEKDAY(DATE(S55,1,4))+1))/7)+1 -> 49 | U55: =IF(T55>=36,S55&"-"&RIGHT(S55+1,2),(S55-1)&"-"&RIGHT(S55,2)) -> 2023-24
... A71: 45376 | B71: 0 | C71: 2 | D71: 1 | E71: 0 | F71: 0 | G71: 3 | H71: 0 | I71: 1 | J71: 1 | K71: 2 | L71: 1 | M71: =IF(AND(K71="",L71=""),"",SUM(K71:L71)) -> 3 | P71: =IF(OR(M71="",M71=0),"",IF(N71="",0,N71)/M71) -> 0 | Q71: MH data from Winter23Tracker | R71: =A71+5 -> 45381 | S71: =IF(R71>=DATE(YEAR(R71)+1,1,4)-WEEKDAY(DATE(YEAR(R71)+1,1,4))+1,YEAR(R71)+1,IF(R71<DATE(YEAR(R71),1,4)-WEEKDAY(DATE(YEAR(R71),1,4))+1,YEAR(R71)-1,YEAR(R71))) -> 2024 | T71: =INT((R71-(DATE(S71,1,4)-WEEKDAY(DATE(S71,1,4))+1))/7)+1 -> 13 | U71: =IF(T71>=36,S71&"-"&RIGHT(S71+1,2),(S71-1)&"-"&RIGHT(S71,2)) -> 2023-24
A72: 45383 | B72: 1 | C72: 5 | D72: 1 | M72: =IF(AND(K72="",L72=""),"",SUM(K72:L72)) | P72: =IF(OR(M72="",M72=0),"",IF(N72="",0,N72)/M72) | R72: =A72+5 -> 45388 | S72: =IF(R72>=DATE(YEAR(R72)+1,1,4)-WEEKDAY(DATE(YEAR(R72)+1,1,4))+1,YEAR(R72)+1,IF(R72<DATE(YEAR(R72),1,4)-WEEKDAY(DATE(YEAR(R72),1,4))+1,YEAR(R72)-1,YEAR(R72))) -> 2024 | T72: =INT((R72-(DATE(S72,1,4)-WEEKDAY(DATE(S72,1,4))+1))/7)+1 -> 14 | U72: =IF(T72>=36,S72&"-"&RIGHT(S72+1,2),(S72-1)&"-"&RIGHT(S72,2)) -> 2023-24
A73: 45390 | B73: 1 | C73: 5 | D73: 0 | M73: =IF(AND(K73="",L73=""),"",SUM(K73:L73)) | P73: =IF(OR(M73="",M73=0),"",IF(N73="",0,N73)/M73) | R73: =A73+5 -> 45395 | S73: =IF(R73>=DATE(YEAR(R73)+1,1,4)-WEEKDAY(DATE(YEAR(R73)+1,1,4))+1,YEAR(R73)+1,IF(R73<DATE(YEAR(R73),1,4)-WEEKDAY(DATE(YEAR(R73),1,4))+1,YEAR(R73)-1,YEAR(R73))) -> 2024 | T73: =INT((R73-(DATE(S73,1,4)-WEEKDAY(DATE(S73,1,4))+1))/7)+1 -> 15 | U73: =IF(T73>=36,S73&"-"&RIGHT(S73+1,2),(S73-1)&"-"&RIGHT(S73,2)) -> 2023-24
A74: 45397 | B74: 1 | C74: 3 | D74: 0 | M74: =IF(AND(K74="",L74=""),"",SUM(K74:L74)) | P74: =IF(OR(M74="",M74=0),"",IF(N74="",0,N74)/M74) | R74: =A74+5 -> 45402 | S74: =IF(R74>=DATE(YEAR(R74)+1,1,4)-WEEKDAY(DATE(YEAR(R74)+1,1,4))+1,YEAR(R74)+1,IF(R74<DATE(YEAR(R74),1,4)-WEEKDAY(DATE(YEAR(R74),1,4))+1,YEAR(R74)-1,YEAR(R74))) -> 2024 | T74: =INT((R74-(DATE(S74,1,4)-WEEKDAY(DATE(S74,1,4))+1))/7)+1 -> 16 | U74: =IF(T74>=36,S74&"-"&RIGHT(S74+1,2),(S74-1)&"-"&RIGHT(S74,2)) -> 2023-24
A75: 45404 | B75: 0 | C75: 1 | D75: 0 | M75: =IF(AND(K75="",L75=""),"",SUM(K75:L75)) | P75: =IF(OR(M75="",M75=0),"",IF(N75="",0,N75)/M75) | R75: =A75+5 -> 45409 | S75: =IF(R75>=DATE(YEAR(R75)+1,1,4)-WEEKDAY(DATE(YEAR(R75)+1,1,4))+1,YEAR(R75)+1,IF(R75<DATE(YEAR(R75),1,4)-WEEKDAY(DATE(YEAR(R75),1,4))+1,YEAR(R75)-1,YEAR(R75))) -> 2024 | T75: =INT((R75-(DATE(S75,1,4)-WEEKDAY(DATE(S75,1,4))+1))/7)+1 -> 17 | U75: =IF(T75>=36,S75&"-"&RIGHT(S75+1,2),(S75-1)&"-"&RIGHT(S75,2)) -> 2023-24
A76: 45411 | B76: 0 | C76: 1 | D76: 0 | M76: =IF(AND(K76="",L76=""),"",SUM(K76:L76)) | P76: =IF(OR(M76="",M76=0),"",IF(N76="",0,N76)/M76) | R76: =A76+5 -> 45416 | S76: =IF(R76>=DATE(YEAR(R76)+1,1,4)-WEEKDAY(DATE(YEAR(R76)+1,1,4))+1,YEAR(R76)+1,IF(R76<DATE(YEAR(R76),1,4)-WEEKDAY(DATE(YEAR(R76),1,4))+1,YEAR(R76)-1,YEAR(R76))) -> 2024 | T76: =INT((R76-(DATE(S76,1,4)-WEEKDAY(DATE(S76,1,4))+1))/7)+1 -> 18 | U76: =IF(T76>=36,S76&"-"&RIGHT(S76+1,2),(S76-1)&"-"&RIGHT(S76,2)) -> 2023-24
A77: 45418 | B77: 1 | C77: 0 | D77: 0 | M77: =IF(AND(K77="",L77=""),"",SUM(K77:L77)) | P77: =IF(OR(M77="",M77=0),"",IF(N77="",0,N77)/M77) | R77: =A77+5 -> 45423 | S77: =IF(R77>=DATE(YEAR(R77)+1,1,4)-WEEKDAY(DATE(YEAR(R77)+1,1,4))+1,YEAR(R77)+1,IF(R77<DATE(YEAR(R77),1,4)-WEEKDAY(DATE(YEAR(R77),1,4))+1,YEAR(R77)-1,YEAR(R77))) -> 2024 | T77: =INT((R77-(DATE(S77,1,4)-WEEKDAY(DATE(S77,1,4))+1))/7)+1 -> 19 | U77: =IF(T77>=36,S77&"-"&RIGHT(S77+1,2),(S77-1)&"-"&RIGHT(S77,2)) -> 2023-24
A78: 45425 | B78: 0 | C78: 1 | D78: 0 | M78: =IF(AND(K78="",L78=""),"",SUM(K78:L78)) | P78: =IF(OR(M78="",M78=0),"",IF(N78="",0,N78)/M78) | R78: =A78+5 -> 45430 | S78: =IF(R78>=DATE(YEAR(R78)+1,1,4)-WEEKDAY(DATE(YEAR(R78)+1,1,4))+1,YEAR(R78)+1,IF(R78<DATE(YEAR(R78),1,4)-WEEKDAY(DATE(YEAR(R78),1,4))+1,YEAR(R78)-1,YEAR(R78))) -> 2024 | T78: =INT((R78-(DATE(S78,1,4)-WEEKDAY(DATE(S78,1,4))+1))/7)+1 -> 20 | U78: =IF(T78>=36,S78&"-"&RIGHT(S78+1,2),(S78-1)&"-"&RIGHT(S78,2)) -> 2023-24
A79: 45432 | B79: 2 | C79: 1 | D79: 0 | M79: =IF(AND(K79="",L79=""),"",SUM(K79:L79)) | P79: =IF(OR(M79="",M79=0),"",IF(N79="",0,N79)/M79) | R79: =A79+5 -> 45437 | S79: =IF(R79>=DATE(YEAR(R79)+1,1,4)-WEEKDAY(DATE(YEAR(R79)+1,1,4))+1,YEAR(R79)+1,IF(R79<DATE(YEAR(R79),1,4)-WEEKDAY(DATE(YEAR(R79),1,4))+1,YEAR(R79)-1,YEAR(R79))) -> 2024 | T79: =INT((R79-(DATE(S79,1,4)-WEEKDAY(DATE(S79,1,4))+1))/7)+1 -> 21 | U79: =IF(T79>=36,S79&"-"&RIGHT(S79+1,2),(S79-1)&"-"&RIGHT(S79,2)) -> 2023-24
A80: 45439 | B80: 1 | C80: 3 | D80: 0 | M80: =IF(AND(K80="",L80=""),"",SUM(K80:L80)) | P80: =IF(OR(M80="",M80=0),"",IF(N80="",0,N80)/M80) | R80: =A80+5 -> 45444 | S80: =IF(R80>=DATE(YEAR(R80)+1,1,4)-WEEKDAY(DATE(YEAR(R80)+1,1,4))+1,YEAR(R80)+1,IF(R80<DATE(YEAR(R80),1,4)-WEEKDAY(DATE(YEAR(R80),1,4))+1,YEAR(R80)-1,YEAR(R80))) -> 2024 | T80: =INT((R80-(DATE(S80,1,4)-WEEKDAY(DATE(S80,1,4))+1))/7)+1 -> 22 | U80: =IF(T80>=36,S80&"-"&RIGHT(S80+1,2),(S80-1)&"-"&RIGHT(S80,2)) -> 2023-24
A81: 45446 | B81: 1 | C81: 3 | D81: 1 | M81: =IF(AND(K81="",L81=""),"",SUM(K81:L81)) | P81: =IF(OR(M81="",M81=0),"",IF(N81="",0,N81)/M81) | R81: =A81+5 -> 45451 | S81: =IF(R81>=DATE(YEAR(R81)+1,1,4)-WEEKDAY(DATE(YEAR(R81)+1,1,4))+1,YEAR(R81)+1,IF(R81<DATE(YEAR(R81),1,4)-WEEKDAY(DATE(YEAR(R81),1,4))+1,YEAR(R81)-1,YEAR(R81))) -> 2024 | T81: =INT((R81-(DATE(S81,1,4)-WEEKDAY(DATE(S81,1,4))+1))/7)+1 -> 23 | U81: =IF(T81>=36,S81&"-"&RIGHT(S81+1,2),(S81-1)&"-"&RIGHT(S81,2)) -> 2023-24
...

Sheet Weekly_ELR
A1: Week (Mon) | B1: Covid positive | C1: Covid negative | D1: Covid % pos | E1: Flu positive | F1: Flu negative | G1: Flu % pos | H1: RSV positive | I1: RSV negative | J1: RSV % pos | K1: Notes
A2: 45285 | B2: 10 | C2: 23 | D2: =IF(SUM(B2:C2)=0,"",B2/SUM(B2:C2)) -> 0.3030303 | E2: 13 | F2: 99 | G2: =IF(SUM(E2:F2)=0,"",E2/SUM(E2:F2)) -> 0.11607143 | H2: 5 | I2: 42 | J2: =IF(SUM(H2:I2)=0,"",H2/SUM(H2:I2)) -> 0.10638298
A3: 45292 | B3: 13 | C3: 17 | D3: =IF(SUM(B3:C3)=0,"",B3/SUM(B3:C3)) -> 0.43333333 | E3: 24 | F3: 132 | G3: =IF(SUM(E3:F3)=0,"",E3/SUM(E3:F3)) -> 0.15384615 | H3: 4 | I3: 57 | J3: =IF(SUM(H3:I3)=0,"",H3/SUM(H3:I3)) -> 0.06557377
A4: 45299 | B4: 8 | C4: 17 | D4: =IF(SUM(B4:C4)=0,"",B4/SUM(B4:C4)) -> 0.32 | E4: 7 | F4: 127 | G4: =IF(SUM(E4:F4)=0,"",E4/SUM(E4:F4)) -> 0.052238806 | H4: 10 | I4: 47 | J4: =IF(SUM(H4:I4)=0,"",H4/SUM(H4:I4)) -> 0.1754386
A5: 45306 | B5: 5 | C5: 17 | D5: =IF(SUM(B5:C5)=0,"",B5/SUM(B5:C5)) -> 0.22727273 | E5: 14 | F5: 112 | G5: =IF(SUM(E5:F5)=0,"",E5/SUM(E5:F5)) -> 0.11111111 | H5: 10 | I5: 42 | J5: =IF(SUM(H5:I5)=0,"",H5/SUM(H5:I5)) -> 0.19230769
A6: 45313 | B6: 5 | C6: 18 | D6: =IF(SUM(B6:C6)=0,"",B6/SUM(B6:C6)) -> 0.2173913 | E6: 6 | F6: 108 | G6: =IF(SUM(E6:F6)=0,"",E6/SUM(E6:F6)) -> 0.052631579 | H6: 5 | I6: 38 | J6: =IF(SUM(H6:I6)=0,"",H6/SUM(H6:I6)) -> 0.11627907
A7: 45320 | B7: 5 | C7: 9 | D7: =IF(SUM(B7:C7)=0,"",B7/SUM(B7:C7)) -> 0.35714286 | E7: 12 | F7: 100 | G7: =IF(SUM(E7:F7)=0,"",E7/SUM(E7:F7)) -> 0.10714286 | H7: 4 | I7: 46 | J7: =IF(SUM(H7:I7)=0,"",H7/SUM(H7:I7)) -> 0.08
A8: 45327 | B8: 2 | C8: 13 | D8: =IF(SUM(B8:C8)=0,"",B8/SUM(B8:C8)) -> 0.13333333 | E8: 8 | F8: 100 | G8: =IF(SUM(E8:F8)=0,"",E8/SUM(E8:F8)) -> 0.074074074 | H8: 5 | I8: 40 | J8: =IF(SUM(H8:I8)=0,"",H8/SUM(H8:I8)) -> 0.11111111
A9: 45334 | B9: 7 | C9: 10 | D9: =IF(SUM(B9:C9)=0,"",B9/SUM(B9:C9)) -> 0.41176471 | E9: 6 | F9: 72 | G9: =IF(SUM(E9:F9)=0,"",E9/SUM(E9:F9)) -> 0.076923077 | H9: 1 | I9: 26 | J9: =IF(SUM(H9:I9)=0,"",H9/SUM(H9:I9)) -> 0.037037037
A10: 45341 | B10: 3 | C10: 8 | D10: =IF(SUM(B10:C10)=0,"",B10/SUM(B10:C10)) -> 0.27272727 | E10: 9 | F10: 77 | G10: =IF(SUM(E10:F10)=0,"",E10/SUM(E10:F10)) -> 0.10465116 | H10: 1 | I10: 30 | J10: =IF(SUM(H10:I10)=0,"",H10/SUM(H10:I10)) -> 0.032258065
A11: 45348 | B11: 2 | C11: 14 | D11: =IF(SUM(B11:C11)=0,"",B11/SUM(B11:C11)) -> 0.125 | E11: 5 | F11: 71 | G11: =IF(SUM(E11:F11)=0,"",E11/SUM(E11:F11)) -> 0.065789474 | H11: 2 | I11: 31 | J11: =IF(SUM(H11:I11)=0,"",H11/SUM(H11:I11)) -> 0.060606061
A12: 45355 | B12: 0 | C12: 11 | D12: =IF(SUM(B12:C12)=0,"",B12/SUM(B12:C12)) -> 0 | E12: 1 | F12: 47 | G12: =IF(SUM(E12:F12)=0,"",E12/SUM(E12:F12)) -> 0.020833333 | H12: 0 | I12: 20 | J12: =IF(SUM(H12:I12)=0,"",H12/SUM(H12:I12)) -> 0
A13: 45537 | B13: 7 | C13: 14 | D13: =IF(SUM(B13:C13)=0,"",B13/SUM(B13:C13)) -> 0.33333333 | E13: 0 | F13: 21 | G13: =IF(SUM(E13:F13)=0,"",E13/SUM(E13:F13)) -> 0 | H13: 0 | I13: 21 | J13: =IF(SUM(H13:I13)=0,"",H13/SUM(H13:I13)) -> 0
... A72: 46104 | B72: 1 | C72: 12 | D72: =IF(SUM(B72:C72)=0,"",B72/SUM(B72:C72)) -> 0.076923077 | E72: 7 | F72: 16 | G72: =IF(SUM(E72:F72)=0,"",E72/SUM(E72:F72)) -> 0.30434783 | H72: 1 | I72: 16 | J72: =IF(SUM(H72:I72)=0,"",H72/SUM(H72:I72)) -> 0.058823529
A73: 46272 | B73: 4 | C73: 5 | D73: =IF(SUM(B73:C73)=0,"",B73/SUM(B73:C73)) -> 0.44444444 | E73: 0 | F73: 9 | G73: =IF(SUM(E73:F73)=0,"",E73/SUM(E73:F73)) -> 0 | H73: 0 | I73: 10 | J73: =IF(SUM(H73:I73)=0,"",H73/SUM(H73:I73)) -> 0 | K73: 2026-27 season starts here
A74: 46279 | B74: 5 | C74: 11 | D74: =IF(SUM(B74:C74)=0,"",B74/SUM(B74:C74)) -> 0.3125 | E74: 1 | F74: 12 | G74: =IF(SUM(E74:F74)=0,"",E74/SUM(E74:F74)) -> 0.076923077 | H74: 0 | I74: 12 | J74: =IF(SUM(H74:I74)=0,"",H74/SUM(H74:I74)) -> 0
A75: 46286 | B75: 4 | C75: 14 | D75: =IF(SUM(B75:C75)=0,"",B75/SUM(B75:C75)) -> 0.22222222 | E75: 0 | F75: 20 | G75: =IF(SUM(E75:F75)=0,"",E75/SUM(E75:F75)) -> 0 | H75: 0 | I75: 18 | J75: =IF(SUM(H75:I75)=0,"",H75/SUM(H75:I75)) -> 0
A76: 46293 | B76: 4 | C76: 9 | D76: =IF(SUM(B76:C76)=0,"",B76/SUM(B76:C76)) -> 0.30769231 | E76: 0 | F76: 14 | G76: =IF(SUM(E76:F76)=0,"",E76/SUM(E76:F76)) -> 0 | H76: 1 | I76: 13 | J76: =IF(SUM(H76:I76)=0,"",H76/SUM(H76:I76)) -> 0.071428571
A77: 46300 | B77: 1 | C77: 6 | D77: =IF(SUM(B77:C77)=0,"",B77/SUM(B77:C77)) -> 0.14285714 | E77: 0 | F77: 11 | G77: =IF(SUM(E77:F77)=0,"",E77/SUM(E77:F77)) -> 0 | H77: 0 | I77: 11 | J77: =IF(SUM(H77:I77)=0,"",H77/SUM(H77:I77)) -> 0
A78: 46307 | D78: =IF(SUM(B78:C78)=0,"",B78/SUM(B78:C78)) | G78: =IF(SUM(E78:F78)=0,"",E78/SUM(E78:F78)) | J78: =IF(SUM(H78:I78)=0,"",H78/SUM(H78:I78))
A79: 46314 | D79: =IF(SUM(B79:C79)=0,"",B79/SUM(B79:C79)) | G79: =IF(SUM(E79:F79)=0,"",E79/SUM(E79:F79)) | J79: =IF(SUM(H79:I79)=0,"",H79/SUM(H79:I79))
A80: 46321 | D80: =IF(SUM(B80:C80)=0,"",B80/SUM(B80:C80)) | G80: =IF(SUM(E80:F80)=0,"",E80/SUM(E80:F80)) | J80: =IF(SUM(H80:I80)=0,"",H80/SUM(H80:I80))
A81: 46328 | D81: =IF(SUM(B81:C81)=0,"",B81/SUM(B81:C81)) | G81: =IF(SUM(E81:F81)=0,"",E81/SUM(E81:F81)) | J81: =IF(SUM(H81:I81)=0,"",H81/SUM(H81:I81))
A82: 46335 | D82: =IF(SUM(B82:C82)=0,"",B82/SUM(B82:C82)) | G82: =IF(SUM(E82:F82)=0,"",E82/SUM(E82:F82)) | J82: =IF(SUM(H82:I82)=0,"",H82/SUM(H82:I82))
A83: 46342 | D83: =IF(SUM(B83:C83)=0,"",B83/SUM(B83:C83)) | G83: =IF(SUM(E83:F83)=0,"",E83/SUM(E83:F83)) | J83: =IF(SUM(H83:I83)=0,"",H83/SUM(H83:I83))
A84: 46349 | D84: =IF(SUM(B84:C84)=0,"",B84/SUM(B84:C84)) | G84: =IF(SUM(E84:F84)=0,"",E84/SUM(E84:F84)) | J84: =IF(SUM(H84:I84)=0,"",H84/SUM(H84:I84))
A85: 46356 | D85: =IF(SUM(B85:C85)=0,"",B85/SUM(B85:C85)) | G85: =IF(SUM(E85:F85)=0,"",E85/SUM(E85:F85)) | J85: =IF(SUM(H85:I85)=0,"",H85/SUM(H85:I85))
A86: 46363 | D86: =IF(SUM(B86:C86)=0,"",B86/SUM(B86:C86)) | G86: =IF(SUM(E86:F86)=0,"",E86/SUM(E86:F86)) | J86: =IF(SUM(H86:I86)=0,"",H86/SUM(H86:I86))
A87: 46370 | D87: =IF(SUM(B87:C87)=0,"",B87/SUM(B87:C87)) | G87: =IF(SUM(E87:F87)=0,"",E87/SUM(E87:F87)) | J87: =IF(SUM(H87:I87)=0,"",H87/SUM(H87:I87))
A88: 46377 | D88: =IF(SUM(B88:C88)=0,"",B88/SUM(B88:C88)) | G88: =IF(SUM(E88:F88)=0,"",E88/SUM(E88:F88)) | J88: =IF(SUM(H88:I88)=0,"",H88/SUM(H88:I88))
A89: 46384 | D89: =IF(SUM(B89:C89)=0,"",B89/SUM(B89:C89)) | G89: =IF(SUM(E89:F89)=0,"",E89/SUM(E89:F89)) | J89: =IF(SUM(H89:I89)=0,"",H89/SUM(H89:I89))
... A111: 46538 | D111: =IF(SUM(B111:C111)=0,"",B111/SUM(B111:C111)) | G111: =IF(SUM(E111:F111)=0,"",E111/SUM(E111:F111)) | J111: =IF(SUM(H111:I111)=0,"",H111/SUM(H111:I111))

Sheet Seasons
A1: Weekly reported cases by MMWR week and season, calculated from Weekly_Local; blank until that week is entered. The dates column shows which Monday–Sunday each MMWR week covers in the season set in Config. MMWR week 53 exists only in some years.
A3: Covid-19
A4: MMWR week | B4: 2022-23 | C4: 2023-24 | D4: 2024-25 | E4: 2025-26 | F4: 2026-27 | G4: Dates, current season (Mon–Sun)
A5: 36 | B5: =IF(COUNTIFS(Weekly_Local!$U:$U,"2022-23",Weekly_Local!$T:$T,$A5,Weekly_Local!$B:$B,"<>")=0,"",SUMIFS(Weekly_Local!$B:$B,Weekly_Local!$U:$U,"2022-23",Weekly_Local!$T:$T,$A5)) | C5: =IF(COUNTIFS(Weekly_Local!$U:$U,"2023-24",Weekly_Local!$T:$T,$A5,Weekly_Local!$B:$B,"<>")=0,"",SUMIFS(Weekly_Local!$B:$B,Weekly_Local!$U:$U,"2023-24",Weekly_Local!$T:$T,$A5)) -> 18 | D5: =IF(COUNTIFS(Weekly_Local!$U:$U,"2024-25",Weekly_Local!$T:$T,$A5,Weekly_Local!$B:$B,"<>")=0,"",SUMIFS(Weekly_Local!$B:$B,Weekly_Local!$U:$U,"2024-25",Weekly_Local!$T:$T,$A5)) -> 6 | E5: =IF(COUNTIFS(Weekly_Local!$U:$U,"2025-26",Weekly_Local!$T:$T,$A5,Weekly_Local!$B:$B,"<>")=0,"",SUMIFS(Weekly_Local!$B:$B,Weekly_Local!$U:$U,"2025-26",Weekly_Local!$T:$T,$A5)) -> 3 | F5: 4 | G5: =IF(AND($A5=53,DATE(YEAR(Config!$B$3),1,4)-WEEKDAY(DATE(YEAR(Config!$B$3),1,4))+1+364>=DATE(YEAR(Config!$B$3)+1,1,4)-WEEKDAY(DATE(YEAR(Config!$B$3)+1,1,4))+1),"",TEXT(DATE(YEAR(Config!$B$3)+IF($A5>=36,0,1),1,4)-WEEKDAY(DATE(YEAR(Config!$B$3)+IF($A5>=36,0,1),1,4))+1+7*($A5-1)+1,"m/d/yy")&" – "&TEXT(DATE(YEAR(Config!$B$3)+IF($A5>=36,0,1),1,4)-WEEKDAY(DATE(YEAR(Config!$B$3)+IF($A5>=36,0,1),1,4))+1+7*($A5-1)+7,"m/d/yy")) -> 9/7/26 – 9/13/26
A6: 37 | B6: =IF(COUNTIFS(Weekly_Local!$U:$U,"2022-23",Weekly_Local!$T:$T,$A6,Weekly_Local!$B:$B,"<>")=0,"",SUMIFS(Weekly_Local!$B:$B,Weekly_Local!$U:$U,"2022-23",Weekly_Local!$T:$T,$A6)) | C6: =IF(COUNTIFS(Weekly_Local!$U:$U,"2023-24",Weekly_Local!$T:$T,$A6,Weekly_Local!$B:$B,"<>")=0,"",SUMIFS(Weekly_Local!$B:$B,Weekly_Local!$U:$U,"2023-24",Weekly_Local!$T:$T,$A6)) -> 5 | D6: =IF(COUNTIFS(Weekly_Local!$U:$U,"2024-25",Weekly_Local!$T:$T,$A6,Weekly_Local!$B:$B,"<>")=0,"",SUMIFS(Weekly_Local!$B:$B,Weekly_Local!$U:$U,"2024-25",Weekly_Local!$T:$T,$A6)) -> 3 | E6: =IF(COUNTIFS(Weekly_Local!$U:$U,"2025-26",Weekly_Local!$T:$T,$A6,Weekly_Local!$B:$B,"<>")=0,"",SUMIFS(Weekly_Local!$B:$B,Weekly_Local!$U:$U,"2025-26",Weekly_Local!$T:$T,$A6)) -> 3 | F6: =IF(COUNTIFS(Weekly_Local!$U:$U,"2026-27",Weekly_Local!$T:$T,$A6,Weekly_Local!$B:$B,"<>")=0,"",SUMIFS(Weekly_Local!$B:$B,Weekly_Local!$U:$U,"2026-27",Weekly_Local!$T:$T,$A6)) -> 5 | G6: =IF(AND($A6=53,DATE(YEAR(Config!$B$3),1,4)-WEEKDAY(DATE(YEAR(Config!$B$3),1,4))+1+364>=DATE(YEAR(Config!$B$3)+1,1,4)-WEEKDAY(DATE(YEAR(Config!$B$3)+1,1,4))+1),"",TEXT(DATE(YEAR(Config!$B$3)+IF($A6>=36,0,1),1,4)-WEEKDAY(DATE(YEAR(Config!$B$3)+IF($A6>=36,0,1),1,4))+1+7*($A6-1)+1,"m/d/yy")&" – "&TEXT(DATE(YEAR(Config!$B$3)+IF($A6>=36,0,1),1,4)-WEEKDAY(DATE(YEAR(Config!$B$3)+IF($A6>=36,0,1),1,4))+1+7*($A6-1)+7,"m/d/yy")) -> 9/14/26 – 9/20/26
A7: 38 | B7: =IF(COUNTIFS(Weekly_Local!$U:$U,"2022-23",Weekly_Local!$T:$T,$A7,Weekly_Local!$B:$B,"<>")=0,"",SUMIFS(Weekly_Local!$B:$B,Weekly_Local!$U:$U,"2022-23",Weekly_Local!$T:$T,$A7)) | C7: =IF(COUNTIFS(Weekly_Local!$U:$U,"2023-24",Weekly_Local!$T:$T,$A7,Weekly_Local!$B:$B,"<>")=0,"",SUMIFS(Weekly_Local!$B:$B,Weekly_Local!$U:$U,"2023-24",Weekly_Local!$T:$T,$A7)) -> 6 | D7: =IF(COUNTIFS(Weekly_Local!$U:$U,"2024-25",Weekly_Local!$T:$T,$A7,Weekly_Local!$B:$B,"<>")=0,"",SUMIFS(Weekly_Local!$B:$B,Weekly_Local!$U:$U,"2024-25",Weekly_Local!$T:$T,$A7)) -> 5 | E7: =IF(COUNTIFS(Weekly_Local!$U:$U,"2025-26",Weekly_Local!$T:$T,$A7,Weekly_Local!$B:$B,"<>")=0,"",SUMIFS(Weekly_Local!$B:$B,Weekly_Local!$U:$U,"2025-26",Weekly_Local!$T:$T,$A7)) -> 3 | F7: =IF(COUNTIFS(Weekly_Local!$U:$U,"2026-27",Weekly_Local!$T:$T,$A7,Weekly_Local!$B:$B,"<>")=0,"",SUMIFS(Weekly_Local!$B:$B,Weekly_Local!$U:$U,"2026-27",Weekly_Local!$T:$T,$A7)) -> 4 | G7: =IF(AND($A7=53,DATE(YEAR(Config!$B$3),1,4)-WEEKDAY(DATE(YEAR(Config!$B$3),1,4))+1+364>=DATE(YEAR(Config!$B$3)+1,1,4)-WEEKDAY(DATE(YEAR(Config!$B$3)+1,1,4))+1),"",TEXT(DATE(YEAR(Config!$B$3)+IF($A7>=36,0,1),1,4)-WEEKDAY(DATE(YEAR(Config!$B$3)+IF($A7>=36,0,1),1,4))+1+7*($A7-1)+1,"m/d/yy")&" – "&TEXT(DATE(YEAR(Config!$B$3)+IF($A7>=36,0,1),1,4)-WEEKDAY(DATE(YEAR(Config!$B$3)+IF($A7>=36,0,1),1,4))+1+7*($A7-1)+7,"m/d/yy")) -> 9/21/26 – 9/27/26
A8: 39 | B8: =IF(COUNTIFS(Weekly_Local!$U:$U,"2022-23",Weekly_Local!$T:$T,$A8,Weekly_Local!$B:$B,"<>")=0,"",SUMIFS(Weekly_Local!$B:$B,Weekly_Local!$U:$U,"2022-23",Weekly_Local!$T:$T,$A8)) | C8: =IF(COUNTIFS(Weekly_Local!$U:$U,"2023-24",Weekly_Local!$T:$T,$A8,Weekly_Local!$B:$B,"<>")=0,"",SUMIFS(Weekly_Local!$B:$B,Weekly_Local!$U:$U,"2023-24",Weekly_Local!$T:$T,$A8)) -> 5 | D8: =IF(COUNTIFS(Weekly_Local!$U:$U,"2024-25",Weekly_Local!$T:$T,$A8,Weekly_Local!$B:$B,"<>")=0,"",SUMIFS(Weekly_Local!$B:$B,Weekly_Local!$U:$U,"2024-25",Weekly_Local!$T:$T,$A8)) -> 8 | E8: =IF(COUNTIFS(Weekly_Local!$U:$U,"2025-26",Weekly_Local!$T:$T,$A8,Weekly_Local!$B:$B,"<>")=0,"",SUMIFS(Weekly_Local!$B:$B,Weekly_Local!$U:$U,"2025-26",Weekly_Local!$T:$T,$A8)) -> 1 | F8: =IF(COUNTIFS(Weekly_Local!$U:$U,"2026-27",Weekly_Local!$T:$T,$A8,Weekly_Local!$B:$B,"<>")=0,"",SUMIFS(Weekly_Local!$B:$B,Weekly_Local!$U:$U,"2026-27",Weekly_Local!$T:$T,$A8)) -> 4 | G8: =IF(AND($A8=53,DATE(YEAR(Config!$B$3),1,4)-WEEKDAY(DATE(YEAR(Config!$B$3),1,4))+1+364>=DATE(YEAR(Config!$B$3)+1,1,4)-WEEKDAY(DATE(YEAR(Config!$B$3)+1,1,4))+1),"",TEXT(DATE(YEAR(Config!$B$3)+IF($A8>=36,0,1),1,4)-WEEKDAY(DATE(YEAR(Config!$B$3)+IF($A8>=36,0,1),1,4))+1+7*($A8-1)+1,"m/d/yy")&" – "&TEXT(DATE(YEAR(Config!$B$3)+IF($A8>=36,0,1),1,4)-WEEKDAY(DATE(YEAR(Config!$B$3)+IF($A8>=36,0,1),1,4))+1+7*($A8-1)+7,"m/d/yy")) -> 9/28/26 – 10/4/26
A9: 40 | B9: =IF(COUNTIFS(Weekly_Local!$U:$U,"2022-23",Weekly_Local!$T:$T,$A9,Weekly_Local!$B:$B,"<>")=0,"",SUMIFS(Weekly_Local!$B:$B,Weekly_Local!$U:$U,"2022-23",Weekly_Local!$T:$T,$A9)) | C9: =IF(COUNTIFS(Weekly_Local!$U:$U,"2023-24",Weekly_Local!$T:$T,$A9,Weekly_Local!$B:$B,"<>")=0,"",SUMIFS(Weekly_Local!$B:$B,Weekly_Local!$U:$U,"2023-24",Weekly_Local!$T:$T,$A9)) -> 1 | D9: =IF(COUNTIFS(Weekly_Local!$U:$U,"2024-25",Weekly_Local!$T:$T,$A9,Weekly_Local!$B:$B,"<>")=0,"",SUMIFS(Weekly_Local!$B:$B,Weekly_Local!$U:$U,"2024-25",Weekly_Local!$T:$T,$A9)) -> 1 | E9: =IF(COUNTIFS(Weekly_Local!$U:$U,"2025-26",Weekly_Local!$T:$T,$A9,Weekly_Local!$B:$B,"<>")=0,"",SUMIFS(Weekly_Local!$B:$B,Weekly_Local!$U:$U,"2025-26",Weekly_Local!$T:$T,$A9)) -> 2 | F9: =IF(COUNTIFS(Weekly_Local!$U:$U,"2026-27",Weekly_Local!$T:$T,$A9,Weekly_Local!$B:$B,"<>")=0,"",SUMIFS(Weekly_Local!$B:$B,Weekly_Local!$U:$U,"2026-27",Weekly_Local!$T:$T,$A9)) -> 1 | G9: =IF(AND($A9=53,DATE(YEAR(Config!$B$3),1,4)-WEEKDAY(DATE(YEAR(Config!$B$3),1,4))+1+364>=DATE(YEAR(Config!$B$3)+1,1,4)-WEEKDAY(DATE(YEAR(Config!$B$3)+1,1,4))+1),"",TEXT(DATE(YEAR(Config!$B$3)+IF($A9>=36,0,1),1,4)-WEEKDAY(DATE(YEAR(Config!$B$3)+IF($A9>=36,0,1),1,4))+1+7*($A9-1)+1,"m/d/yy")&" – "&TEXT(DATE(YEAR(Config!$B$3)+IF($A9>=36,0,1),1,4)-WEEKDAY(DATE(YEAR(Config!$B$3)+IF($A9>=36,0,1),1,4))+1+7*($A9-1)+7,"m/d/yy")) -> 10/5/26 – 10/11/26
A10: 41 | B10: =IF(COUNTIFS(Weekly_Local!$U:$U,"2022-23",Weekly_Local!$T:$T,$A10,Weekly_Local!$B:$B,"<>")=0,"",SUMIFS(Weekly_Local!$B:$B,Weekly_Local!$U:$U,"2022-23",Weekly_Local!$T:$T,$A10)) | C10: =IF(COUNTIFS(Weekly_Local!$U:$U,"2023-24",Weekly_Local!$T:$T,$A10,Weekly_Local!$B:$B,"<>")=0,"",SUMIFS(Weekly_Local!$B:$B,Weekly_Local!$U:$U,"2023-24",Weekly_Local!$T:$T,$A10)) -> 14 | D10: =IF(COUNTIFS(Weekly_Local!$U:$U,"2024-25",Weekly_Local!$T:$T,$A10,Weekly_Local!$B:$B,"<>")=0,"",SUMIFS(Weekly_Local!$B:$B,Weekly_Local!$U:$U,"2024-25",Weekly_Local!$T:$T,$A10)) -> 1 | E10: =IF(COUNTIFS(Weekly_Local!$U:$U,"2025-26",Weekly_Local!$T:$T,$A10,Weekly_Local!$B:$B,"<>")=0,"",SUMIFS(Weekly_Local!$B:$B,Weekly_Local!$U:$U,"2025-26",Weekly_Local!$T:$T,$A10)) -> 1 | F10: =IF(COUNTIFS(Weekly_Local!$U:$U,"2026-27",Weekly_Local!$T:$T,$A10,Weekly_Local!$B:$B,"<>")=0,"",SUMIFS(Weekly_Local!$B:$B,Weekly_Local!$U:$U,"2026-27",Weekly_Local!$T:$T,$A10)) | G10: =IF(AND($A10=53,DATE(YEAR(Config!$B$3),1,4)-WEEKDAY(DATE(YEAR(Config!$B$3),1,4))+1+364>=DATE(YEAR(Config!$B$3)+1,1,4)-WEEKDAY(DATE(YEAR(Config!$B$3)+1,1,4))+1),"",TEXT(DATE(YEAR(Config!$B$3)+IF($A10>=36,0,1),1,4)-WEEKDAY(DATE(YEAR(Config!$B$3)+IF($A10>=36,0,1),1,4))+1+7*($A10-1)+1,"m/d/yy")&" – "&TEXT(DATE(YEAR(Config!$B$3)+IF($A10>=36,0,1),1,4)-WEEKDAY(DATE(YEAR(Config!$B$3)+IF($A10>=36,0,1),1,4))+1+7*($A10-1)+7,"m/d/yy")) -> 10/12/26 – 10/18/26
A11: 42 | B11: =IF(COUNTIFS(Weekly_Local!$U:$U,"2022-23",Weekly_Local!$T:$T,$A11,Weekly_Local!$B:$B,"<>")=0,"",SUMIFS(Weekly_Local!$B:$B,Weekly_Local!$U:$U,"2022-23",Weekly_Local!$T:$T,$A11)) | C11: =IF(COUNTIFS(Weekly_Local!$U:$U,"2023-24",Weekly_Local!$T:$T,$A11,Weekly_Local!$B:$B,"<>")=0,"",SUMIFS(Weekly_Local!$B:$B,Weekly_Local!$U:$U,"2023-24",Weekly_Local!$T:$T,$A11)) -> 7 | D11: =IF(COUNTIFS(Weekly_Local!$U:$U,"2024-25",Weekly_Local!$T:$T,$A11,Weekly_Local!$B:$B,"<>")=0,"",SUMIFS(Weekly_Local!$B:$B,Weekly_Local!$U:$U,"2024-25",Weekly_Local!$T:$T,$A11)) -> 2 | E11: =IF(COUNTIFS(Weekly_Local!$U:$U,"2025-26",Weekly_Local!$T:$T,$A11,Weekly_Local!$B:$B,"<>")=0,"",SUMIFS(Weekly_Local!$B:$B,Weekly_Local!$U:$U,"2025-26",Weekly_Local!$T:$T,$A11)) -> 0 | F11: =IF(COUNTIFS(Weekly_Local!$U:$U,"2026-27",Weekly_Local!$T:$T,$A11,Weekly_Local!$B:$B,"<>")=0,"",SUMIFS(Weekly_Local!$B:$B,Weekly_Local!$U:$U,"2026-27",Weekly_Local!$T:$T,$A11)) | G11: =IF(AND($A11=53,DATE(YEAR(Config!$B$3),1,4)-WEEKDAY(DATE(YEAR(Config!$B$3),1,4))+1+364>=DATE(YEAR(Config!$B$3)+1,1,4)-WEEKDAY(DATE(YEAR(Config!$B$3)+1,1,4))+1),"",TEXT(DATE(YEAR(Config!$B$3)+IF($A11>=36,0,1),1,4)-WEEKDAY(DATE(YEAR(Config!$B$3)+IF($A11>=36,0,1),1,4))+1+7*($A11-1)+1,"m/d/yy")&" – "&TEXT(DATE(YEAR(Config!$B$3)+IF($A11>=36,0,1),1,4)-WEEKDAY(DATE(YEAR(Config!$B$3)+IF($A11>=36,0,1),1,4))+1+7*($A11-1)+7,"m/d/yy")) -> 10/19/26 – 10/25/26
A12: 43 | B12: =IF(COUNTIFS(Weekly_Local!$U:$U,"2022-23",Weekly_Local!$T:$T,$A12,Weekly_Local!$B:$B,"<>")=0,"",SUMIFS(Weekly_Local!$B:$B,Weekly_Local!$U:$U,"2022-23",Weekly_Local!$T:$T,$A12)) | C12: =IF(COUNTIFS(Weekly_Local!$U:$U,"2023-24",Weekly_Local!$T:$T,$A12,Weekly_Local!$B:$B,"<>")=0,"",SUMIFS(Weekly_Local!$B:$B,Weekly_Local!$U:$U,"2023-24",Weekly_Local!$T:$T,$A12)) -> 0 | D12: =IF(COUNTIFS(Weekly_Local!$U:$U,"2024-25",Weekly_Local!$T:$T,$A12,Weekly_Local!$B:$B,"<>")=0,"",SUMIFS(Weekly_Local!$B:$B,Weekly_Local!$U:$U,"2024-25",Weekly_Local!$T:$T,$A12)) -> 3 | E12: =IF(COUNTIFS(Weekly_Local!$U:$U,"2025-26",Weekly_Local!$T:$T,$A12,Weekly_Local!$B:$B,"<>")=0,"",SUMIFS(Weekly_Local!$B:$B,Weekly_Local!$U:$U,"2025-26",Weekly_Local!$T:$T,$A12)) -> 0 | F12: =IF(COUNTIFS(Weekly_Local!$U:$U,"2026-27",Weekly_Local!$T:$T,$A12,Weekly_Local!$B:$B,"<>")=0,"",SUMIFS(Weekly_Local!$B:$B,Weekly_Local!$U:$U,"2026-27",Weekly_Local!$T:$T,$A12)) | G12: =IF(AND($A12=53,DATE(YEAR(Config!$B$3),1,4)-WEEKDAY(DATE(YEAR(Config!$B$3),1,4))+1+364>=DATE(YEAR(Config!$B$3)+1,1,4)-WEEKDAY(DATE(YEAR(Config!$B$3)+1,1,4))+1),"",TEXT(DATE(YEAR(Config!$B$3)+IF($A12>=36,0,1),1,4)-WEEKDAY(DATE(YEAR(Config!$B$3)+IF($A12>=36,0,1),1,4))+1+7*($A12-1)+1,"m/d/yy")&" – "&TEXT(DATE(YEAR(Config!$B$3)+IF($A12>=36,0,1),1,4)-WEEKDAY(DATE(YEAR(Config!$B$3)+IF($A12>=36,0,1),1,4))+1+7*($A12-1)+7,"m/d/yy")) -> 10/26/26 – 11/1/26
A13: 44 | B13: =IF(COUNTIFS(Weekly_Local!$U:$U,"2022-23",Weekly_Local!$T:$T,$A13,Weekly_Local!$B:$B,"<>")=0,"",SUMIFS(Weekly_Local!$B:$B,Weekly_Local!$U:$U,"2022-23",Weekly_Local!$T:$T,$A13)) | C13: =IF(COUNTIFS(Weekly_Local!$U:$U,"2023-24",Weekly_Local!$T:$T,$A13,Weekly_Local!$B:$B,"<>")=0,"",SUMIFS(Weekly_Local!$B:$B,Weekly_Local!$U:$U,"2023-24",Weekly_Local!$T:$T,$A13)) -> 13 | D13: =IF(COUNTIFS(Weekly_Local!$U:$U,"2024-25",Weekly_Local!$T:$T,$A13,Weekly_Local!$B:$B,"<>")=0,"",SUMIFS(Weekly_Local!$B:$B,Weekly_Local!$U:$U,"2024-25",Weekly_Local!$T:$T,$A13)) -> 2 | E13: =IF(COUNTIFS(Weekly_Local!$U:$U,"2025-26",Weekly_Local!$T:$T,$A13,Weekly_Local!$B:$B,"<>")=0,"",SUMIFS(Weekly_Local!$B:$B,Weekly_Local!$U:$U,"2025-26",Weekly_Local!$T:$T,$A13)) -> 0 | F13: =IF(COUNTIFS(Weekly_Local!$U:$U,"2026-27",Weekly_Local!$T:$T,$A13,Weekly_Local!$B:$B,"<>")=0,"",SUMIFS(Weekly_Local!$B:$B,Weekly_Local!$U:$U,"2026-27",Weekly_Local!$T:$T,$A13)) | G13: =IF(AND($A13=53,DATE(YEAR(Config!$B$3),1,4)-WEEKDAY(DATE(YEAR(Config!$B$3),1,4))+1+364>=DATE(YEAR(Config!$B$3)+1,1,4)-WEEKDAY(DATE(YEAR(Config!$B$3)+1,1,4))+1),"",TEXT(DATE(YEAR(Config!$B$3)+IF($A13>=36,0,1),1,4)-WEEKDAY(DATE(YEAR(Config!$B$3)+IF($A13>=36,0,1),1,4))+1+7*($A13-1)+1,"m/d/yy")&" – "&TEXT(DATE(YEAR(Config!$B$3)+IF($A13>=36,0,1),1,4)-WEEKDAY(DATE(YEAR(Config!$B$3)+IF($A13>=36,0,1),1,4))+1+7*($A13-1)+7,"m/d/yy")) -> 11/2/26 – 11/8/26
A14: 45 | B14: =IF(COUNTIFS(Weekly_Local!$U:$U,"2022-23",Weekly_Local!$T:$T,$A14,Weekly_Local!$B:$B,"<>")=0,"",SUMIFS(Weekly_Local!$B:$B,Weekly_Local!$U:$U,"2022-23",Weekly_Local!$T:$T,$A14)) | C14: =IF(COUNTIFS(Weekly_Local!$U:$U,"2023-24",Weekly_Local!$T:$T,$A14,Weekly_Local!$B:$B,"<>")=0,"",SUMIFS(Weekly_Local!$B:$B,Weekly_Local!$U:$U,"2023-24",Weekly_Local!$T:$T,$A14)) -> 6 | D14: =IF(COUNTIFS(Weekly_Local!$U:$U,"2024-25",Weekly_Local!$T:$T,$A14,Weekly_Local!$B:$B,"<>")=0,"",SUMIFS(Weekly_Local!$B:$B,Weekly_Local!$U:$U,"2024-25",Weekly_Local!$T:$T,$A14)) -> 2 | E14: =IF(COUNTIFS(Weekly_Local!$U:$U,"2025-26",Weekly_Local!$T:$T,$A14,Weekly_Local!$B:$B,"<>")=0,"",SUMIFS(Weekly_Local!$B:$B,Weekly_Local!$U:$U,"2025-26",Weekly_Local!$T:$T,$A14)) -> 2 | F14: =IF(COUNTIFS(Weekly_Local!$U:$U,"2026-27",Weekly_Local!$T:$T,$A14,Weekly_Local!$B:$B,"<>")=0,"",SUMIFS(Weekly_Local!$B:$B,Weekly_Local!$U:$U,"2026-27",Weekly_Local!$T:$T,$A14)) | G14: =IF(AND($A14=53,DATE(YEAR(Config!$B$3),1,4)-WEEKDAY(DATE(YEAR(Config!$B$3),1,4))+1+364>=DATE(YEAR(Config!$B$3)+1,1,4)-WEEKDAY(DATE(YEAR(Config!$B$3)+1,1,4))+1),"",TEXT(DATE(YEAR(Config!$B$3)+IF($A14>=36,0,1),1,4)-WEEKDAY(DATE(YEAR(Config!$B$3)+IF($A14>=36,0,1),1,4))+1+7*($A14-1)+1,"m/d/yy")&" – "&TEXT(DATE(YEAR(Config!$B$3)+IF($A14>=36,0,1),1,4)-WEEKDAY(DATE(YEAR(Config!$B$3)+IF($A14>=36,0,1),1,4))+1+7*($A14-1)+7,"m/d/yy")) -> 11/9/26 – 11/15/26
A15: 46 | B15: =IF(COUNTIFS(Weekly_Local!$U:$U,"2022-23",Weekly_Local!$T:$T,$A15,Weekly_Local!$B:$B,"<>")=0,"",SUMIFS(Weekly_Local!$B:$B,Weekly_Local!$U:$U,"2022-23",Weekly_Local!$T:$T,$A15)) | C15: =IF(COUNTIFS(Weekly_Local!$U:$U,"2023-24",Weekly_Local!$T:$T,$A15,Weekly_Local!$B:$B,"<>")=0,"",SUMIFS(Weekly_Local!$B:$B,Weekly_Local!$U:$U,"2023-24",Weekly_Local!$T:$T,$A15)) -> 0 | D15: =IF(COUNTIFS(Weekly_Local!$U:$U,"2024-25",Weekly_Local!$T:$T,$A15,Weekly_Local!$B:$B,"<>")=0,"",SUMIFS(Weekly_Local!$B:$B,Weekly_Local!$U:$U,"2024-25",Weekly_Local!$T:$T,$A15)) -> 1 | E15: =IF(COUNTIFS(Weekly_Local!$U:$U,"2025-26",Weekly_Local!$T:$T,$A15,Weekly_Local!$B:$B,"<>")=0,"",SUMIFS(Weekly_Local!$B:$B,Weekly_Local!$U:$U,"2025-26",Weekly_Local!$T:$T,$A15)) -> 2 | F15: =IF(COUNTIFS(Weekly_Local!$U:$U,"2026-27",Weekly_Local!$T:$T,$A15,Weekly_Local!$B:$B,"<>")=0,"",SUMIFS(Weekly_Local!$B:$B,Weekly_Local!$U:$U,"2026-27",Weekly_Local!$T:$T,$A15)) | G15: =IF(AND($A15=53,DATE(YEAR(Config!$B$3),1,4)-WEEKDAY(DATE(YEAR(Config!$B$3),1,4))+1+364>=DATE(YEAR(Config!$B$3)+1,1,4)-WEEKDAY(DATE(YEAR(Config!$B$3)+1,1,4))+1),"",TEXT(DATE(YEAR(Config!$B$3)+IF($A15>=36,0,1),1,4)-WEEKDAY(DATE(YEAR(Config!$B$3)+IF($A15>=36,0,1),1,4))+1+7*($A15-1)+1,"m/d/yy")&" – "&TEXT(DATE(YEAR(Config!$B$3)+IF($A15>=36,0,1),1,4)-WEEKDAY(DATE(YEAR(Config!$B$3)+IF($A15>=36,0,1),1,4))+1+7*($A15-1)+7,"m/d/yy")) -> 11/16/26 – 11/22/26
A16: 47 | B16: =IF(COUNTIFS(Weekly_Local!$U:$U,"2022-23",Weekly_Local!$T:$T,$A16,Weekly_Local!$B:$B,"<>")=0,"",SUMIFS(Weekly_Local!$B:$B,Weekly_Local!$U:$U,"2022-23",Weekly_Local!$T:$T,$A16)) | C16: =IF(COUNTIFS(Weekly_Local!$U:$U,"2023-24",Weekly_Local!$T:$T,$A16,Weekly_Local!$B:$B,"<>")=0,"",SUMIFS(Weekly_Local!$B:$B,Weekly_Local!$U:$U,"2023-24",Weekly_Local!$T:$T,$A16)) -> 2 | D16: =IF(COUNTIFS(Weekly_Local!$U:$U,"2024-25",Weekly_Local!$T:$T,$A16,Weekly_Local!$B:$B,"<>")=0,"",SUMIFS(Weekly_Local!$B:$B,Weekly_Local!$U:$U,"2024-25",Weekly_Local!$T:$T,$A16)) -> 0 | E16: =IF(COUNTIFS(Weekly_Local!$U:$U,"2025-26",Weekly_Local!$T:$T,$A16,Weekly_Local!$B:$B,"<>")=0,"",SUMIFS(Weekly_Local!$B:$B,Weekly_Local!$U:$U,"2025-26",Weekly_Local!$T:$T,$A16)) -> 0 | F16: =IF(COUNTIFS(Weekly_Local!$U:$U,"2026-27",Weekly_Local!$T:$T,$A16,Weekly_Local!$B:$B,"<>")=0,"",SUMIFS(Weekly_Local!$B:$B,Weekly_Local!$U:$U,"2026-27",Weekly_Local!$T:$T,$A16)) | G16: =IF(AND($A16=53,DATE(YEAR(Config!$B$3),1,4)-WEEKDAY(DATE(YEAR(Config!$B$3),1,4))+1+364>=DATE(YEAR(Config!$B$3)+1,1,4)-WEEKDAY(DATE(YEAR(Config!$B$3)+1,1,4))+1),"",TEXT(DATE(YEAR(Config!$B$3)+IF($A16>=36,0,1),1,4)-WEEKDAY(DATE(YEAR(Config!$B$3)+IF($A16>=36,0,1),1,4))+1+7*($A16-1)+1,"m/d/yy")&" – "&TEXT(DATE(YEAR(Config!$B$3)+IF($A16>=36,0,1),1,4)-WEEKDAY(DATE(YEAR(Config!$B$3)+IF($A16>=36,0,1),1,4))+1+7*($A16-1)+7,"m/d/yy")) -> 11/23/26 – 11/29/26
A17: 48 | B17: =IF(COUNTIFS(Weekly_Local!$U:$U,"2022-23",Weekly_Local!$T:$T,$A17,Weekly_Local!$B:$B,"<>")=0,"",SUMIFS(Weekly_Local!$B:$B,Weekly_Local!$U:$U,"2022-23",Weekly_Local!$T:$T,$A17)) -> 2 | C17: =IF(COUNTIFS(Weekly_Local!$U:$U,"2023-24",Weekly_Local!$T:$T,$A17,Weekly_Local!$B:$B,"<>")=0,"",SUMIFS(Weekly_Local!$B:$B,Weekly_Local!$U:$U,"2023-24",Weekly_Local!$T:$T,$A17)) -> 9 | D17: =IF(COUNTIFS(Weekly_Local!$U:$U,"2024-25",Weekly_Local!$T:$T,$A17,Weekly_Local!$B:$B,"<>")=0,"",SUMIFS(Weekly_Local!$B:$B,Weekly_Local!$U:$U,"2024-25",Weekly_Local!$T:$T,$A17)) -> 1 | E17: =IF(COUNTIFS(Weekly_Local!$U:$U,"2025-26",Weekly_Local!$T:$T,$A17,Weekly_Local!$B:$B,"<>")=0,"",SUMIFS(Weekly_Local!$B:$B,Weekly_Local!$U:$U,"2025-26",Weekly_Local!$T:$T,$A17)) -> 3 | F17: =IF(COUNTIFS(Weekly_Local!$U:$U,"2026-27",Weekly_Local!$T:$T,$A17,Weekly_Local!$B:$B,"<>")=0,"",SUMIFS(Weekly_Local!$B:$B,Weekly_Local!$U:$U,"2026-27",Weekly_Local!$T:$T,$A17)) | G17: =IF(AND($A17=53,DATE(YEAR(Config!$B$3),1,4)-WEEKDAY(DATE(YEAR(Config!$B$3),1,4))+1+364>=DATE(YEAR(Config!$B$3)+1,1,4)-WEEKDAY(DATE(YEAR(Config!$B$3)+1,1,4))+1),"",TEXT(DATE(YEAR(Config!$B$3)+IF($A17>=36,0,1),1,4)-WEEKDAY(DATE(YEAR(Config!$B$3)+IF($A17>=36,0,1),1,4))+1+7*($A17-1)+1,"m/d/yy")&" – "&TEXT(DATE(YEAR(Config!$B$3)+IF($A17>=36,0,1),1,4)-WEEKDAY(DATE(YEAR(Config!$B$3)+IF($A17>=36,0,1),1,4))+1+7*($A17-1)+7,"m/d/yy")) -> 11/30/26 – 12/6/26
... A57: 35 | B57: =IF(COUNTIFS(Weekly_Local!$U:$U,"2022-23",Weekly_Local!$T:$T,$A57,Weekly_Local!$B:$B,"<>")=0,"",SUMIFS(Weekly_Local!$B:$B,Weekly_Local!$U:$U,"2022-23",Weekly_Local!$T:$T,$A57)) -> 18 | C57: =IF(COUNTIFS(Weekly_Local!$U:$U,"2023-24",Weekly_Local!$T:$T,$A57,Weekly_Local!$B:$B,"<>")=0,"",SUMIFS(Weekly_Local!$B:$B,Weekly_Local!$U:$U,"2023-24",Weekly_Local!$T:$T,$A57)) -> 5 | D57: =IF(COUNTIFS(Weekly_Local!$U:$U,"2024-25",Weekly_Local!$T:$T,$A57,Weekly_Local!$B:$B,"<>")=0,"",SUMIFS(Weekly_Local!$B:$B,Weekly_Local!$U:$U,"2024-25",Weekly_Local!$T:$T,$A57)) -> 6 | E57: =IF(COUNTIFS(Weekly_Local!$U:$U,"2025-26",Weekly_Local!$T:$T,$A57,Weekly_Local!$B:$B,"<>")=0,"",SUMIFS(Weekly_Local!$B:$B,Weekly_Local!$U:$U,"2025-26",Weekly_Local!$T:$T,$A57)) -> 0 | F57: =IF(COUNTIFS(Weekly_Local!$U:$U,"2026-27",Weekly_Local!$T:$T,$A57,Weekly_Local!$B:$B,"<>")=0,"",SUMIFS(Weekly_Local!$B:$B,Weekly_Local!$U:$U,"2026-27",Weekly_Local!$T:$T,$A57)) | G57: =IF(AND($A57=53,DATE(YEAR(Config!$B$3),1,4)-WEEKDAY(DATE(YEAR(Config!$B$3),1,4))+1+364>=DATE(YEAR(Config!$B$3)+1,1,4)-WEEKDAY(DATE(YEAR(Config!$B$3)+1,1,4))+1),"",TEXT(DATE(YEAR(Config!$B$3)+IF($A57>=36,0,1),1,4)-WEEKDAY(DATE(YEAR(Config!$B$3)+IF($A57>=36,0,1),1,4))+1+7*($A57-1)+1,"m/d/yy")&" – "&TEXT(DATE(YEAR(Config!$B$3)+IF($A57>=36,0,1),1,4)-WEEKDAY(DATE(YEAR(Config!$B$3)+IF($A57>=36,0,1),1,4))+1+7*($A57-1)+7,"m/d/yy")) -> 8/30/27 – 9/5/27
A60: Flu
A61: MMWR week | B61: 2022-23 | C61: 2023-24 | D61: 2024-25 | E61: 2025-26 | F61: 2026-27 | G61: Dates, current season (Mon–Sun)
A62: 36 | B62: =IF(COUNTIFS(Weekly_Local!$U:$U,"2022-23",Weekly_Local!$T:$T,$A62,Weekly_Local!$C:$C,"<>")=0,"",SUMIFS(Weekly_Local!$C:$C,Weekly_Local!$U:$U,"2022-23",Weekly_Local!$T:$T,$A62)) | C62: =IF(COUNTIFS(Weekly_Local!$U:$U,"2023-24",Weekly_Local!$T:$T,$A62,Weekly_Local!$C:$C,"<>")=0,"",SUMIFS(Weekly_Local!$C:$C,Weekly_Local!$U:$U,"2023-24",Weekly_Local!$T:$T,$A62)) -> 0 | D62: =IF(COUNTIFS(Weekly_Local!$U:$U,"2024-25",Weekly_Local!$T:$T,$A62,Weekly_Local!$C:$C,"<>")=0,"",SUMIFS(Weekly_Local!$C:$C,Weekly_Local!$U:$U,"2024-25",Weekly_Local!$T:$T,$A62)) -> 0 | E62: =IF(COUNTIFS(Weekly_Local!$U:$U,"2025-26",Weekly_Local!$T:$T,$A62,Weekly_Local!$C:$C,"<>")=0,"",SUMIFS(Weekly_Local!$C:$C,Weekly_Local!$U:$U,"2025-26",Weekly_Local!$T:$T,$A62)) -> 0 | F62: 0 | G62: =IF(AND($A62=53,DATE(YEAR(Config!$B$3),1,4)-WEEKDAY(DATE(YEAR(Config!$B$3),1,4))+1+364>=DATE(YEAR(Config!$B$3)+1,1,4)-WEEKDAY(DATE(YEAR(Config!$B$3)+1,1,4))+1),"",TEXT(DATE(YEAR(Config!$B$3)+IF($A62>=36,0,1),1,4)-WEEKDAY(DATE(YEAR(Config!$B$3)+IF($A62>=36,0,1),1,4))+1+7*($A62-1)+1,"m/d/yy")&" – "&TEXT(DATE(YEAR(Config!$B$3)+IF($A62>=36,0,1),1,4)-WEEKDAY(DATE(YEAR(Config!$B$3)+IF($A62>=36,0,1),1,4))+1+7*($A62-1)+7,"m/d/yy")) -> 9/7/26 – 9/13/26
A63: 37 | B63: =IF(COUNTIFS(Weekly_Local!$U:$U,"2022-23",Weekly_Local!$T:$T,$A63,Weekly_Local!$C:$C,"<>")=0,"",SUMIFS(Weekly_Local!$C:$C,Weekly_Local!$U:$U,"2022-23",Weekly_Local!$T:$T,$A63)) | C63: =IF(COUNTIFS(Weekly_Local!$U:$U,"2023-24",Weekly_Local!$T:$T,$A63,Weekly_Local!$C:$C,"<>")=0,"",SUMIFS(Weekly_Local!$C:$C,Weekly_Local!$U:$U,"2023-24",Weekly_Local!$T:$T,$A63)) -> 0 | D63: =IF(COUNTIFS(Weekly_Local!$U:$U,"2024-25",Weekly_Local!$T:$T,$A63,Weekly_Local!$C:$C,"<>")=0,"",SUMIFS(Weekly_Local!$C:$C,Weekly_Local!$U:$U,"2024-25",Weekly_Local!$T:$T,$A63)) -> 1 | E63: =IF(COUNTIFS(Weekly_Local!$U:$U,"2025-26",Weekly_Local!$T:$T,$A63,Weekly_Local!$C:$C,"<>")=0,"",SUMIFS(Weekly_Local!$C:$C,Weekly_Local!$U:$U,"2025-26",Weekly_Local!$T:$T,$A63)) -> 0 | F63: =IF(COUNTIFS(Weekly_Local!$U:$U,"2026-27",Weekly_Local!$T:$T,$A63,Weekly_Local!$C:$C,"<>")=0,"",SUMIFS(Weekly_Local!$C:$C,Weekly_Local!$U:$U,"2026-27",Weekly_Local!$T:$T,$A63)) -> 1 | G63: =IF(AND($A63=53,DATE(YEAR(Config!$B$3),1,4)-WEEKDAY(DATE(YEAR(Config!$B$3),1,4))+1+364>=DATE(YEAR(Config!$B$3)+1,1,4)-WEEKDAY(DATE(YEAR(Config!$B$3)+1,1,4))+1),"",TEXT(DATE(YEAR(Config!$B$3)+IF($A63>=36,0,1),1,4)-WEEKDAY(DATE(YEAR(Config!$B$3)+IF($A63>=36,0,1),1,4))+1+7*($A63-1)+1,"m/d/yy")&" – "&TEXT(DATE(YEAR(Config!$B$3)+IF($A63>=36,0,1),1,4)-WEEKDAY(DATE(YEAR(Config!$B$3)+IF($A63>=36,0,1),1,4))+1+7*($A63-1)+7,"m/d/yy")) -> 9/14/26 – 9/20/26
A64: 38 | B64: =IF(COUNTIFS(Weekly_Local!$U:$U,"2022-23",Weekly_Local!$T:$T,$A64,Weekly_Local!$C:$C,"<>")=0,"",SUMIFS(Weekly_Local!$C:$C,Weekly_Local!$U:$U,"2022-23",Weekly_Local!$T:$T,$A64)) | C64: =IF(COUNTIFS(Weekly_Local!$U:$U,"2023-24",Weekly_Local!$T:$T,$A64,Weekly_Local!$C:$C,"<>")=0,"",SUMIFS(Weekly_Local!$C:$C,Weekly_Local!$U:$U,"2023-24",Weekly_Local!$T:$T,$A64)) -> 2 | D64: =IF(COUNTIFS(Weekly_Local!$U:$U,"2024-25",Weekly_Local!$T:$T,$A64,Weekly_Local!$C:$C,"<>")=0,"",SUMIFS(Weekly_Local!$C:$C,Weekly_Local!$U:$U,"2024-25",Weekly_Local!$T:$T,$A64)) -> 1 | E64: =IF(COUNTIFS(Weekly_Local!$U:$U,"2025-26",Weekly_Local!$T:$T,$A64,Weekly_Local!$C:$C,"<>")=0,"",SUMIFS(Weekly_Local!$C:$C,Weekly_Local!$U:$U,"2025-26",Weekly_Local!$T:$T,$A64)) -> 0 | F64: =IF(COUNTIFS(Weekly_Local!$U:$U,"2026-27",Weekly_Local!$T:$T,$A64,Weekly_Local!$C:$C,"<>")=0,"",SUMIFS(Weekly_Local!$C:$C,Weekly_Local!$U:$U,"2026-27",Weekly_Local!$T:$T,$A64)) -> 0 | G64: =IF(AND($A64=53,DATE(YEAR(Config!$B$3),1,4)-WEEKDAY(DATE(YEAR(Config!$B$3),1,4))+1+364>=DATE(YEAR(Config!$B$3)+1,1,4)-WEEKDAY(DATE(YEAR(Config!$B$3)+1,1,4))+1),"",TEXT(DATE(YEAR(Config!$B$3)+IF($A64>=36,0,1),1,4)-WEEKDAY(DATE(YEAR(Config!$B$3)+IF($A64>=36,0,1),1,4))+1+7*($A64-1)+1,"m/d/yy")&" – "&TEXT(DATE(YEAR(Config!$B$3)+IF($A64>=36,0,1),1,4)-WEEKDAY(DATE(YEAR(Config!$B$3)+IF($A64>=36,0,1),1,4))+1+7*($A64-1)+7,"m/d/yy")) -> 9/21/26 – 9/27/26
A65: 39 | B65: =IF(COUNTIFS(Weekly_Local!$U:$U,"2022-23",Weekly_Local!$T:$T,$A65,Weekly_Local!$C:$C,"<>")=0,"",SUMIFS(Weekly_Local!$C:$C,Weekly_Local!$U:$U,"2022-23",Weekly_Local!$T:$T,$A65)) | C65: =IF(COUNTIFS(Weekly_Local!$U:$U,"2023-24",Weekly_Local!$T:$T,$A65,Weekly_Local!$C:$C,"<>")=0,"",SUMIFS(Weekly_Local!$C:$C,Weekly_Local!$U:$U,"2023-24",Weekly_Local!$T:$T,$A65)) -> 0 | D65: =IF(COUNTIFS(Weekly_Local!$U:$U,"2024-25",Weekly_Local!$T:$T,$A65,Weekly_Local!$C:$C,"<>")=0,"",SUMIFS(Weekly_Local!$C:$C,Weekly_Local!$U:$U,"2024-25",Weekly_Local!$T:$T,$A65)) -> 0 | E65: =IF(COUNTIFS(Weekly_Local!$U:$U,"2025-26",Weekly_Local!$T:$T,$A65,Weekly_Local!$C:$C,"<>")=0,"",SUMIFS(Weekly_Local!$C:$C,Weekly_Local!$U:$U,"2025-26",Weekly_Local!$T:$T,$A65)) -> 0 | F65: =IF(COUNTIFS(Weekly_Local!$U:$U,"2026-27",Weekly_Local!$T:$T,$A65,Weekly_Local!$C:$C,"<>")=0,"",SUMIFS(Weekly_Local!$C:$C,Weekly_Local!$U:$U,"2026-27",Weekly_Local!$T:$T,$A65)) -> 0 | G65: =IF(AND($A65=53,DATE(YEAR(Config!$B$3),1,4)-WEEKDAY(DATE(YEAR(Config!$B$3),1,4))+1+364>=DATE(YEAR(Config!$B$3)+1,1,4)-WEEKDAY(DATE(YEAR(Config!$B$3)+1,1,4))+1),"",TEXT(DATE(YEAR(Config!$B$3)+IF($A65>=36,0,1),1,4)-WEEKDAY(DATE(YEAR(Config!$B$3)+IF($A65>=36,0,1),1,4))+1+7*($A65-1)+1,"m/d/yy")&" – "&TEXT(DATE(YEAR(Config!$B$3)+IF($A65>=36,0,1),1,4)-WEEKDAY(DATE(YEAR(Config!$B$3)+IF($A65>=36,0,1),1,4))+1+7*($A65-1)+7,"m/d/yy")) -> 9/28/26 – 10/4/26
A66: 40 | B66: =IF(COUNTIFS(Weekly_Local!$U:$U,"2022-23",Weekly_Local!$T:$T,$A66,Weekly_Local!$C:$C,"<>")=0,"",SUMIFS(Weekly_Local!$C:$C,Weekly_Local!$U:$U,"2022-23",Weekly_Local!$T:$T,$A66)) | C66: =IF(COUNTIFS(Weekly_Local!$U:$U,"2023-24",Weekly_Local!$T:$T,$A66,Weekly_Local!$C:$C,"<>")=0,"",SUMIFS(Weekly_Local!$C:$C,Weekly_Local!$U:$U,"2023-24",Weekly_Local!$T:$T,$A66)) -> 0 | D66: =IF(COUNTIFS(Weekly_Local!$U:$U,"2024-25",Weekly_Local!$T:$T,$A66,Weekly_Local!$C:$C,"<>")=0,"",SUMIFS(Weekly_Local!$C:$C,Weekly_Local!$U:$U,"2024-25",Weekly_Local!$T:$T,$A66)) -> 0 | E66: =IF(COUNTIFS(Weekly_Local!$U:$U,"2025-26",Weekly_Local!$T:$T,$A66,Weekly_Local!$C:$C,"<>")=0,"",SUMIFS(Weekly_Local!$C:$C,Weekly_Local!$U:$U,"2025-26",Weekly_Local!$T:$T,$A66)) -> 0 | F66: =IF(COUNTIFS(Weekly_Local!$U:$U,"2026-27",Weekly_Local!$T:$T,$A66,Weekly_Local!$C:$C,"<>")=0,"",SUMIFS(Weekly_Local!$C:$C,Weekly_Local!$U:$U,"2026-27",Weekly_Local!$T:$T,$A66)) -> 0 | G66: =IF(AND($A66=53,DATE(YEAR(Config!$B$3),1,4)-WEEKDAY(DATE(YEAR(Config!$B$3),1,4))+1+364>=DATE(YEAR(Config!$B$3)+1,1,4)-WEEKDAY(DATE(YEAR(Config!$B$3)+1,1,4))+1),"",TEXT(DATE(YEAR(Config!$B$3)+IF($A66>=36,0,1),1,4)-WEEKDAY(DATE(YEAR(Config!$B$3)+IF($A66>=36,0,1),1,4))+1+7*($A66-1)+1,"m/d/yy")&" – "&TEXT(DATE(YEAR(Config!$B$3)+IF($A66>=36,0,1),1,4)-WEEKDAY(DATE(YEAR(Config!$B$3)+IF($A66>=36,0,1),1,4))+1+7*($A66-1)+7,"m/d/yy")) -> 10/5/26 – 10/11/26
A67: 41 | B67: =IF(COUNTIFS(Weekly_Local!$U:$U,"2022-23",Weekly_Local!$T:$T,$A67,Weekly_Local!$C:$C,"<>")=0,"",SUMIFS(Weekly_Local!$C:$C,Weekly_Local!$U:$U,"2022-23",Weekly_Local!$T:$T,$A67)) | C67: =IF(COUNTIFS(Weekly_Local!$U:$U,"2023-24",Weekly_Local!$T:$T,$A67,Weekly_Local!$C:$C,"<>")=0,"",SUMIFS(Weekly_Local!$C:$C,Weekly_Local!$U:$U,"2023-24",Weekly_Local!$T:$T,$A67)) -> 0 | D67: =IF(COUNTIFS(Weekly_Local!$U:$U,"2024-25",Weekly_Local!$T:$T,$A67,Weekly_Local!$C:$C,"<>")=0,"",SUMIFS(Weekly_Local!$C:$C,Weekly_Local!$U:$U,"2024-25",Weekly_Local!$T:$T,$A67)) -> 0 | E67: =IF(COUNTIFS(Weekly_Local!$U:$U,"2025-26",Weekly_Local!$T:$T,$A67,Weekly_Local!$C:$C,"<>")=0,"",SUMIFS(Weekly_Local!$C:$C,Weekly_Local!$U:$U,"2025-26",Weekly_Local!$T:$T,$A67)) -> 0 | F67: =IF(COUNTIFS(Weekly_Local!$U:$U,"2026-27",Weekly_Local!$T:$T,$A67,Weekly_Local!$C:$C,"<>")=0,"",SUMIFS(Weekly_Local!$C:$C,Weekly_Local!$U:$U,"2026-27",Weekly_Local!$T:$T,$A67)) | G67: =IF(AND($A67=53,DATE(YEAR(Config!$B$3),1,4)-WEEKDAY(DATE(YEAR(Config!$B$3),1,4))+1+364>=DATE(YEAR(Config!$B$3)+1,1,4)-WEEKDAY(DATE(YEAR(Config!$B$3)+1,1,4))+1),"",TEXT(DATE(YEAR(Config!$B$3)+IF($A67>=36,0,1),1,4)-WEEKDAY(DATE(YEAR(Config!$B$3)+IF($A67>=36,0,1),1,4))+1+7*($A67-1)+1,"m/d/yy")&" – "&TEXT(DATE(YEAR(Config!$B$3)+IF($A67>=36,0,1),1,4)-WEEKDAY(DATE(YEAR(Config!$B$3)+IF($A67>=36,0,1),1,4))+1+7*($A67-1)+7,"m/d/yy")) -> 10/12/26 – 10/18/26
A68: 42 | B68: =IF(COUNTIFS(Weekly_Local!$U:$U,"2022-23",Weekly_Local!$T:$T,$A68,Weekly_Local!$C:$C,"<>")=0,"",SUMIFS(Weekly_Local!$C:$C,Weekly_Local!$U:$U,"2022-23",Weekly_Local!$T:$T,$A68)) | C68: =IF(COUNTIFS(Weekly_Local!$U:$U,"2023-24",Weekly_Local!$T:$T,$A68,Weekly_Local!$C:$C,"<>")=0,"",SUMIFS(Weekly_Local!$C:$C,Weekly_Local!$U:$U,"2023-24",Weekly_Local!$T:$T,$A68)) -> 0 | D68: =IF(COUNTIFS(Weekly_Local!$U:$U,"2024-25",Weekly_Local!$T:$T,$A68,Weekly_Local!$C:$C,"<>")=0,"",SUMIFS(Weekly_Local!$C:$C,Weekly_Local!$U:$U,"2024-25",Weekly_Local!$T:$T,$A68)) -> 0 | E68: =IF(COUNTIFS(Weekly_Local!$U:$U,"2025-26",Weekly_Local!$T:$T,$A68,Weekly_Local!$C:$C,"<>")=0,"",SUMIFS(Weekly_Local!$C:$C,Weekly_Local!$U:$U,"2025-26",Weekly_Local!$T:$T,$A68)) -> 0 | F68: =IF(COUNTIFS(Weekly_Local!$U:$U,"2026-27",Weekly_Local!$T:$T,$A68,Weekly_Local!$C:$C,"<>")=0,"",SUMIFS(Weekly_Local!$C:$C,Weekly_Local!$U:$U,"2026-27",Weekly_Local!$T:$T,$A68)) | G68: =IF(AND($A68=53,DATE(YEAR(Config!$B$3),1,4)-WEEKDAY(DATE(YEAR(Config!$B$3),1,4))+1+364>=DATE(YEAR(Config!$B$3)+1,1,4)-WEEKDAY(DATE(YEAR(Config!$B$3)+1,1,4))+1),"",TEXT(DATE(YEAR(Config!$B$3)+IF($A68>=36,0,1),1,4)-WEEKDAY(DATE(YEAR(Config!$B$3)+IF($A68>=36,0,1),1,4))+1+7*($A68-1)+1,"m/d/yy")&" – "&TEXT(DATE(YEAR(Config!$B$3)+IF($A68>=36,0,1),1,4)-WEEKDAY(DATE(YEAR(Config!$B$3)+IF($A68>=36,0,1),1,4))+1+7*($A68-1)+7,"m/d/yy")) -> 10/19/26 – 10/25/26
A69: 43 | B69: =IF(COUNTIFS(Weekly_Local!$U:$U,"2022-23",Weekly_Local!$T:$T,$A69,Weekly_Local!$C:$C,"<>")=0,"",SUMIFS(Weekly_Local!$C:$C,Weekly_Local!$U:$U,"2022-23",Weekly_Local!$T:$T,$A69)) | C69: =IF(COUNTIFS(Weekly_Local!$U:$U,"2023-24",Weekly_Local!$T:$T,$A69,Weekly_Local!$C:$C,"<>")=0,"",SUMIFS(Weekly_Local!$C:$C,Weekly_Local!$U:$U,"2023-24",Weekly_Local!$T:$T,$A69)) -> 0 | D69: =IF(COUNTIFS(Weekly_Local!$U:$U,"2024-25",Weekly_Local!$T:$T,$A69,Weekly_Local!$C:$C,"<>")=0,"",SUMIFS(Weekly_Local!$C:$C,Weekly_Local!$U:$U,"2024-25",Weekly_Local!$T:$T,$A69)) -> 2 | E69: =IF(COUNTIFS(Weekly_Local!$U:$U,"2025-26",Weekly_Local!$T:$T,$A69,Weekly_Local!$C:$C,"<>")=0,"",SUMIFS(Weekly_Local!$C:$C,Weekly_Local!$U:$U,"2025-26",Weekly_Local!$T:$T,$A69)) -> 0 | F69: =IF(COUNTIFS(Weekly_Local!$U:$U,"2026-27",Weekly_Local!$T:$T,$A69,Weekly_Local!$C:$C,"<>")=0,"",SUMIFS(Weekly_Local!$C:$C,Weekly_Local!$U:$U,"2026-27",Weekly_Local!$T:$T,$A69)) | G69: =IF(AND($A69=53,DATE(YEAR(Config!$B$3),1,4)-WEEKDAY(DATE(YEAR(Config!$B$3),1,4))+1+364>=DATE(YEAR(Config!$B$3)+1,1,4)-WEEKDAY(DATE(YEAR(Config!$B$3)+1,1,4))+1),"",TEXT(DATE(YEAR(Config!$B$3)+IF($A69>=36,0,1),1,4)-WEEKDAY(DATE(YEAR(Config!$B$3)+IF($A69>=36,0,1),1,4))+1+7*($A69-1)+1,"m/d/yy")&" – "&TEXT(DATE(YEAR(Config!$B$3)+IF($A69>=36,0,1),1,4)-WEEKDAY(DATE(YEAR(Config!$B$3)+IF($A69>=36,0,1),1,4))+1+7*($A69-1)+7,"m/d/yy")) -> 10/26/26 – 11/1/26
